Workbook

Sheet 사용법
B2: 모의고사 성적표 (2026 고3 심화 모의평가 27차)
B5: 이 파일 하나로 한 회차가 끝납니다
B6: 회차마다 새 파일을 만들지 마시고, 이 파일을 복사해서 이름만 바꿔 쓰십시오. (예: 모의고사-성적표-28차.xlsx)
B8: 1단계 · 회차설정 시트 — 회차마다 여기만 고칩니다
B9: · 시험 이름, 시행일, 등급컷을 적습니다. · 영역 표: 어느 문항이 어느 영역인지 적습니다. (예: 독서론 1~3) · 문항별 정답·배점: 답지를 보고 그대로 옮겨 적습니다. · 다 적으면 맨 위 '확인' 칸에 '정상입니다'가 뜹니다. 빨간 글씨가 뜨면 배점 합계나 영역 표의 시작·끝 번호를 다시 보십시오. (이 확인이 지난 시트의 118% 오류를 막아 줍니다) · 27차 값은 이미 채워 넣었습니다. 등급컷만 확인해 주십시오.
B11: 2단계 · 답안입력 시트 — 학생 OMR을 옮겨 적습니다
B12: · 한 줄에 학생 한 명입니다. 이름 / 학년 / 선택과목을 적고 1~45번 답을 적습니다. · 빠른 방법: '한 번에 입력' 칸에 45자리를 이어서 붙여 넣으면 됩니다. (예: 434255332… 45글자) 이 칸이 채워져 있으면 옆의 낱칸은 비워 두어도 됩니다. · 선택과목에 따라 35~45번은 알아서 다른 정답표로 채점됩니다. · 맨 오른쪽에 점수와 등급이 바로 나옵니다.
B14: 3단계 · 성적표 시트 — 한 명씩 보고 인쇄합니다
B15: · 맨 위 이름 칸을 누르면 학생 목록이 펼쳐집니다. 고르면 성적표가 그 학생 것으로 바뀝니다. · 그대로 인쇄하면 A4 한 장입니다.
B17: 4단계 · 성적표(전원) 시트 — 한 번에 모두 인쇄합니다
B18: · 답안입력에 적은 학생들의 성적표가 위에서부터 차례로 들어 있습니다. · 학생마다 쪽이 나뉘어 있어서, 그냥 인쇄하면 전원 성적표가 한 번에 나옵니다. · 학생이 없는 자리는 빈 쪽이 되니, 인쇄할 쪽 범위만 정해 주시면 됩니다.
B20: 5단계 · 분석 시트 — 반 전체를 봅니다
... B27: 이 파일은 이번 주를 넘기기 위한 것입니다. 학생이 휴대폰으로 답을 직접 넣고 성적표가 바로 나오는 앱(B안)을 이어서 만듭니다.

Sheet 회차설정
A1: 회차 설정 — 회차마다 이 시트만 고치면 됩니다
A2: 시험 이름 | B2: 2026 고3 심화 모의평가 27차
A3: 시행일 | F3: ← 시험 본 날짜를 적어 주세요
A4: 확인 | B4: =IF(AND(SUM($C$32:$C$65)+SUM($G$32:$G$42)=100,SUM($C$32:$C$65)+SUM($K$32:$K$42)=100,MIN(자동계산!$F$4:$F$48)=1,MAX(자동계산!$F$4:$F$48)=1,MIN(자동계산!$G$4:$G$48)=1,MAX(자동계산!$G$4:$G$48)=1),"정상입니다 — 배점 합계 100점, 영역 표가 45문항을 빠짐없이 덮습니다","확인이 필요합니다 — 배점 합계가 100점인지, 영역 표의 시작·끝 번호가 겹치거나 빠지지 않았는지 보세요")
A6: ■ 등급컷 (이 점수 이상이면 그 등급입니다)
A7: 선택과목 | B7: 1등급 | C7: 2등급 | D7: 3등급 | E7: 4등급
A8: 화법과 작문 | B8: 90 | C8: 84 | D8: 76 | E8: 62 | F8: ← 지난 26차 값입니다. 이번 회차 등급컷으로 고쳐 주세요
A9: 언어와 매체 | B9: 90 | C9: 84 | D9: 76 | E9: 62
A11: ■ 영역 표 — 어느 문항이 어느 영역인지 (공통을 먼저, 그다음 선택과목)
A12: 분류 | B12: 영역 | C12: 시작번호 | D12: 끝번호 | E12: 대상 | F12: 화작순번 | G12: 언매순번 | I12: 대상 칸에는 셋 중 하나를 적습니다: 공통 / 화법과 작문 / 언어와 매체 회색 두 칸은 자동입니다. 고치지 마세요.
A13: 독서 | B13: 독서론 | C13: 1 | D13: 3 | E13: 공통 | F13: =IF(OR($E13="공통",$E13="화법과 작문"),COUNTIF($E$13:$E13,"공통")+COUNTIF($E$13:$E13,"화법과 작문"),"") | G13: =IF(OR($E13="공통",$E13="언어와 매체"),COUNTIF($E$13:$E13,"공통")+COUNTIF($E$13:$E13,"언어와 매체"),"")
A14: 독서 | B14: 사회 | C14: 4 | D14: 9 | E14: 공통 | F14: =IF(OR($E14="공통",$E14="화법과 작문"),COUNTIF($E$13:$E14,"공통")+COUNTIF($E$13:$E14,"화법과 작문"),"") | G14: =IF(OR($E14="공통",$E14="언어와 매체"),COUNTIF($E$13:$E14,"공통")+COUNTIF($E$13:$E14,"언어와 매체"),"")
A15: 독서 | B15: 기술 | C15: 10 | D15: 13 | E15: 공통 | F15: =IF(OR($E15="공통",$E15="화법과 작문"),COUNTIF($E$13:$E15,"공통")+COUNTIF($E$13:$E15,"화법과 작문"),"") | G15: =IF(OR($E15="공통",$E15="언어와 매체"),COUNTIF($E$13:$E15,"공통")+COUNTIF($E$13:$E15,"언어와 매체"),"")
A16: 독서 | B16: 인문 | C16: 14 | D16: 17 | E16: 공통 | F16: =IF(OR($E16="공통",$E16="화법과 작문"),COUNTIF($E$13:$E16,"공통")+COUNTIF($E$13:$E16,"화법과 작문"),"") | G16: =IF(OR($E16="공통",$E16="언어와 매체"),COUNTIF($E$13:$E16,"공통")+COUNTIF($E$13:$E16,"언어와 매체"),"")
A17: 문학 | B17: 현대소설 | C17: 18 | D17: 21 | E17: 공통 | F17: =IF(OR($E17="공통",$E17="화법과 작문"),COUNTIF($E$13:$E17,"공통")+COUNTIF($E$13:$E17,"화법과 작문"),"") | G17: =IF(OR($E17="공통",$E17="언어와 매체"),COUNTIF($E$13:$E17,"공통")+COUNTIF($E$13:$E17,"언어와 매체"),"")
A18: 문학 | B18: 갈래복합 | C18: 22 | D18: 27 | E18: 공통 | F18: =IF(OR($E18="공통",$E18="화법과 작문"),COUNTIF($E$13:$E18,"공통")+COUNTIF($E$13:$E18,"화법과 작문"),"") | G18: =IF(OR($E18="공통",$E18="언어와 매체"),COUNTIF($E$13:$E18,"공통")+COUNTIF($E$13:$E18,"언어와 매체"),"")
A19: 문학 | B19: 고전소설 | C19: 28 | D19: 31 | E19: 공통 | F19: =IF(OR($E19="공통",$E19="화법과 작문"),COUNTIF($E$13:$E19,"공통")+COUNTIF($E$13:$E19,"화법과 작문"),"") | G19: =IF(OR($E19="공통",$E19="언어와 매체"),COUNTIF($E$13:$E19,"공통")+COUNTIF($E$13:$E19,"언어와 매체"),"")
A20: 문학 | B20: 고전시가 | C20: 32 | D20: 34 | E20: 공통 | F20: =IF(OR($E20="공통",$E20="화법과 작문"),COUNTIF($E$13:$E20,"공통")+COUNTIF($E$13:$E20,"화법과 작문"),"") | G20: =IF(OR($E20="공통",$E20="언어와 매체"),COUNTIF($E$13:$E20,"공통")+COUNTIF($E$13:$E20,"언어와 매체"),"")
A21: 선택과목 | B21: 화법 | C21: 35 | D21: 37 | E21: 화법과 작문 | F21: =IF(OR($E21="공통",$E21="화법과 작문"),COUNTIF($E$13:$E21,"공통")+COUNTIF($E$13:$E21,"화법과 작문"),"") | G21: =IF(OR($E21="공통",$E21="언어와 매체"),COUNTIF($E$13:$E21,"공통")+COUNTIF($E$13:$E21,"언어와 매체"),"")
A22: 선택과목 | B22: 화법+작문 | C22: 38 | D22: 42 | E22: 화법과 작문 | F22: =IF(OR($E22="공통",$E22="화법과 작문"),COUNTIF($E$13:$E22,"공통")+COUNTIF($E$13:$E22,"화법과 작문"),"") | G22: =IF(OR($E22="공통",$E22="언어와 매체"),COUNTIF($E$13:$E22,"공통")+COUNTIF($E$13:$E22,"언어와 매체"),"")
A23: 선택과목 | B23: 작문 | C23: 43 | D23: 45 | E23: 화법과 작문 | F23: =IF(OR($E23="공통",$E23="화법과 작문"),COUNTIF($E$13:$E23,"공통")+COUNTIF($E$13:$E23,"화법과 작문"),"") | G23: =IF(OR($E23="공통",$E23="언어와 매체"),COUNTIF($E$13:$E23,"공통")+COUNTIF($E$13:$E23,"언어와 매체"),"")
A24: 선택과목 | B24: 언어 | C24: 35 | D24: 39 | E24: 언어와 매체 | F24: =IF(OR($E24="공통",$E24="화법과 작문"),COUNTIF($E$13:$E24,"공통")+COUNTIF($E$13:$E24,"화법과 작문"),"") | G24: =IF(OR($E24="공통",$E24="언어와 매체"),COUNTIF($E$13:$E24,"공통")+COUNTIF($E$13:$E24,"언어와 매체"),"")
A25: 선택과목 | B25: 매체 | C25: 40 | D25: 45 | E25: 언어와 매체 | F25: =IF(OR($E25="공통",$E25="화법과 작문"),COUNTIF($E$13:$E25,"공통")+COUNTIF($E$13:$E25,"화법과 작문"),"") | G25: =IF(OR($E25="공통",$E25="언어와 매체"),COUNTIF($E$13:$E25,"공통")+COUNTIF($E$13:$E25,"언어와 매체"),"")
F26: =IF(OR($E26="공통",$E26="화법과 작문"),COUNTIF($E$13:$E26,"공통")+COUNTIF($E$13:$E26,"화법과 작문"),"") | G26: =IF(OR($E26="공통",$E26="언어와 매체"),COUNTIF($E$13:$E26,"공통")+COUNTIF($E$13:$E26,"언어와 매체"),"")
F27: =IF(OR($E27="공통",$E27="화법과 작문"),COUNTIF($E$13:$E27,"공통")+COUNTIF($E$13:$E27,"화법과 작문"),"") | G27: =IF(OR($E27="공통",$E27="언어와 매체"),COUNTIF($E$13:$E27,"공통")+COUNTIF($E$13:$E27,"언어와 매체"),"")
A29: ■ 문항별 정답·배점 — 답지를 보고 그대로 옮겨 적습니다
A30: 공통과목 (1~34번) | E30: 선택과목 · 화법과 작문 (35~45번) | I30: 선택과목 · 언어와 매체 (35~45번)
A31: 번호 | B31: 정답 | C31: 배점 | E31: 번호 | F31: 정답 | G31: 배점 | I31: 번호 | J31: 정답 | K31: 배점
A32: 1 | B32: 4 | C32: 2 | E32: 35 | F32: 1 | G32: 2 | I32: 35 | J32: 2 | K32: 2
A33: 2 | B33: 3 | C33: 2 | E33: 36 | F33: 5 | G33: 2 | I33: 36 | J33: 5 | K33: 3
A34: 3 | B34: 4 | C34: 3 | E34: 37 | F34: 3 | G34: 2 | I34: 37 | J34: 1 | K34: 2
A35: 4 | B35: 4 | C35: 2 | E35: 38 | F35: 4 | G35: 2 | I35: 38 | J35: 4 | K35: 2
A36: 5 | B36: 5 | C36: 2 | E36: 39 | F36: 3 | G36: 2 | I36: 39 | J36: 2 | K36: 2
A37: 6 | B37: 2 | C37: 2 | E37: 40 | F37: 5 | G37: 3 | I37: 40 | J37: 3 | K37: 2
A38: 7 | B38: 3 | C38: 2 | E38: 41 | F38: 4 | G38: 2 | I38: 41 | J38: 4 | K38: 2
A39: 8 | B39: 3 | C39: 3 | E39: 42 | F39: 1 | G39: 2 | I39: 42 | J39: 1 | K39: 2
A40: 9 | B40: 1 | C40: 2 | E40: 43 | F40: 2 | G40: 2 | I40: 43 | J40: 5 | K40: 3
A41: 10 | B41: 3 | C41: 2 | E41: 44 | F41: 5 | G41: 2 | I41: 44 | J41: 4 | K41: 2
A42: 11 | B42: 1 | C42: 2 | E42: 45 | F42: 4 | G42: 3 | I42: 45 | J42: 5 | K42: 2
A43: 12 | B43: 3 | C43: 3 | E43: 배점 합계 | G43: =SUM(G32:G42) | I43: 배점 합계 | K43: =SUM(K32:K42)
...

Sheet 답안입력
A1: 학생 답안 입력 — 한 줄에 학생 한 명 | F1: 빠른 방법: '한 번에 입력' 칸에 45자리를 이어 붙여 넣으세요 (예 434255332…). 그 칸이 채워져 있으면 옆의 낱칸은 비워 두어도 됩니다.
A2: 이름 | B2: 학년 | C2: 선택과목 | D2: 한 번에 입력 (45자리) | E2: 1 | F2: 2 | G2: 3 | H2: 4 | I2: 5 | J2: 6 | K2: 7 | L2: 8 | M2: 9 | N2: 10 | O2: 11 | P2: 12 | Q2: 13 | R2: 14 | S2: 15 | T2: 16 | U2: 17 | V2: 18 | W2: 19 | X2: 20 | Y2: 21 | Z2: 22 | AA2: 23 | AB2: 24 | AC2: 25 | AD2: 26 | AE2: 27 | AF2: 28 | AG2: 29 | AH2: 30 | AI2: 31 | AJ2: 32 | AK2: 33 | AL2: 34 | AM2: 35 | AN2: 36 | AO2: 37 | AP2: 38 | AQ2: 39 | AR2: 40 | AS2: 41 | AT2: 42 | AU2: 43 | AV2: 44 | AW2: 45 | AX2: 점수 | AY2: 등급
AX3: =IF($A3="","",전체채점!$C3) | AY3: =IF($A3="","",전체채점!$D3)
AX4: =IF($A4="","",전체채점!$C4) | AY4: =IF($A4="","",전체채점!$D4)
AX5: =IF($A5="","",전체채점!$C5) | AY5: =IF($A5="","",전체채점!$D5)
AX6: =IF($A6="","",전체채점!$C6) | AY6: =IF($A6="","",전체채점!$D6)
AX7: =IF($A7="","",전체채점!$C7) | AY7: =IF($A7="","",전체채점!$D7)
AX8: =IF($A8="","",전체채점!$C8) | AY8: =IF($A8="","",전체채점!$D8)
AX9: =IF($A9="","",전체채점!$C9) | AY9: =IF($A9="","",전체채점!$D9)
AX10: =IF($A10="","",전체채점!$C10) | AY10: =IF($A10="","",전체채점!$D10)
AX11: =IF($A11="","",전체채점!$C11) | AY11: =IF($A11="","",전체채점!$D11)
AX12: =IF($A12="","",전체채점!$C12) | AY12: =IF($A12="","",전체채점!$D12)
AX13: =IF($A13="","",전체채점!$C13) | AY13: =IF($A13="","",전체채점!$D13)
AX14: =IF($A14="","",전체채점!$C14) | AY14: =IF($A14="","",전체채점!$D14)
... AX62: =IF($A62="","",전체채점!$C62) | AY62: =IF($A62="","",전체채점!$D62)

Sheet 성적표
A1: =IF($R$3="","",회차설정!$B$2&" 성적표")
A3: 1. 학생정보 | R3: =IFERROR(MATCH($A$5,답안입력!$A$3:$A$62,0),"") | S3: =IF($R$4="","",IFERROR(IF($R$4="언어와 매체",MATCH(1,회차설정!$G$13:$G$27,0),MATCH(1,회차설정!$F$13:$F$27,0)),""))
A4: 성명 | D4: 선택과목 | H4: 학년 | L4: 시행일 | R4: =IF($R$3="","",INDEX(전체채점!$B$3:$B$62,$R$3)) | S4: =IF($R$4="","",IFERROR(IF($R$4="언어와 매체",MATCH(2,회차설정!$G$13:$G$27,0),MATCH(2,회차설정!$F$13:$F$27,0)),""))
A5: =IF($R$3="","",INDEX(답안입력!$A$3:$A$62,$R$3)) | D5: =IF($R$3="","",INDEX(답안입력!$C$3:$C$62,$R$3)) | H5: =IF($R$3="","",INDEX(답안입력!$B$3:$B$62,$R$3)) | L5: =회차설정!$B$3 | R5: =IF($R$4="언어와 매체",회차설정!$B$9,회차설정!$B$8) | S5: =IF($R$4="","",IFERROR(IF($R$4="언어와 매체",MATCH(3,회차설정!$G$13:$G$27,0),MATCH(3,회차설정!$F$13:$F$27,0)),""))
R6: =IF($R$4="언어와 매체",회차설정!$C$9,회차설정!$C$8) | S6: =IF($R$4="","",IFERROR(IF($R$4="언어와 매체",MATCH(4,회차설정!$G$13:$G$27,0),MATCH(4,회차설정!$F$13:$F$27,0)),""))
A7: 2. 성적 | R7: =IF($R$4="언어와 매체",회차설정!$D$9,회차설정!$D$8) | S7: =IF($R$4="","",IFERROR(IF($R$4="언어와 매체",MATCH(5,회차설정!$G$13:$G$27,0),MATCH(5,회차설정!$F$13:$F$27,0)),""))
A8: 점수 (100점 만점) | F8: 등급 | I8: 등급컷 | M8: 같은 선택과목 평균 | R8: =IF($R$4="언어와 매체",회차설정!$E$9,회차설정!$E$8) | S8: =IF($R$4="","",IFERROR(IF($R$4="언어와 매체",MATCH(6,회차설정!$G$13:$G$27,0),MATCH(6,회차설정!$F$13:$F$27,0)),""))
A9: =IF($R$3="","",INDEX(전체채점!$C$3:$C$62,$R$3)) | F9: =IF($R$3="","",INDEX(전체채점!$D$3:$D$62,$R$3)) | I9: =IF($R$3="","",$R$5&"-"&$R$6&"-"&$R$7&"-"&$R$8) | M9: =IFERROR(AVERAGEIF(전체채점!$B$3:$B$62,$R$4,전체채점!$C$3:$C$62),"") | S9: =IF($R$4="","",IFERROR(IF($R$4="언어와 매체",MATCH(7,회차설정!$G$13:$G$27,0),MATCH(7,회차설정!$F$13:$F$27,0)),""))
S10: =IF($R$4="","",IFERROR(IF($R$4="언어와 매체",MATCH(8,회차설정!$G$13:$G$27,0),MATCH(8,회차설정!$F$13:$F$27,0)),""))
A11: 3. 영역분류별 성취도 분석 | F11: =IF(OR($R$3="",$E25=""),"",IF($E25=INDEX(전체채점!$C$3:$C$62,$R$3),"","※ 회차설정의 영역 표를 확인하세요 — 영역 합계와 점수가 다릅니다")) | S11: =IF($R$4="","",IFERROR(IF($R$4="언어와 매체",MATCH(9,회차설정!$G$13:$G$27,0),MATCH(9,회차설정!$F$13:$F$27,0)),""))
A12: 분류 | B12: 영역 | D12: 배점 | E12: 득점 | F12: 성취도(%) | S12: =IF($R$4="","",IFERROR(IF($R$4="언어와 매체",MATCH(10,회차설정!$G$13:$G$27,0),MATCH(10,회차설정!$F$13:$F$27,0)),""))
A13: =IF($S$3="","",INDEX(회차설정!$A$13:$A$27,$S$3)) | B13: =IF($S$3="","",INDEX(회차설정!$B$13:$B$27,$S$3)) | D13: =IF($S$3="","",IF($R$4="언어와 매체",SUMPRODUCT((자동계산!$A$4:$A$48>=INDEX(회차설정!$C$13:$C$27,$S$3))*(자동계산!$A$4:$A$48<=INDEX(회차설정!$D$13:$D$27,$S$3))*자동계산!$E$4:$E$48),SUMPRODUCT((자동계산!$A$4:$A$48>=INDEX(회차설정!$C$13:$C$27,$S$3))*(자동계산!$A$4:$A$48<=INDEX(회차설정!$D$13:$D$27,$S$3))*자동계산!$C$4:$C$48))) | E13: =IF(OR($S$3="",$R$3=""),"",SUM(OFFSET(전체채점!$AW$2,$R$3,INDEX(회차설정!$C$13:$C$27,$S$3),1,INDEX(회차설정!$D$13:$D$27,$S$3)-INDEX(회차설정!$C$13:$C$27,$S$3)+1))) | F13: =IF(OR($S$3="",$D13=0,$D13="",$E13=""),"",$E13/$D13*100) | H13: =IF($F13="","",REPT("■",ROUND($F13/5,0))) | S13: =IF($R$4="","",IFERROR(IF($R$4="언어와 매체",MATCH(11,회차설정!$G$13:$G$27,0),MATCH(11,회차설정!$F$13:$F$27,0)),""))
A14: =IF($S$4="","",INDEX(회차설정!$A$13:$A$27,$S$4)) | B14: =IF($S$4="","",INDEX(회차설정!$B$13:$B$27,$S$4)) | D14: =IF($S$4="","",IF($R$4="언어와 매체",SUMPRODUCT((자동계산!$A$4:$A$48>=INDEX(회차설정!$C$13:$C$27,$S$4))*(자동계산!$A$4:$A$48<=INDEX(회차설정!$D$13:$D$27,$S$4))*자동계산!$E$4:$E$48),SUMPRODUCT((자동계산!$A$4:$A$48>=INDEX(회차설정!$C$13:$C$27,$S$4))*(자동계산!$A$4:$A$48<=INDEX(회차설정!$D$13:$D$27,$S$4))*자동계산!$C$4:$C$48))) | E14: =IF(OR($S$4="",$R$3=""),"",SUM(OFFSET(전체채점!$AW$2,$R$3,INDEX(회차설정!$C$13:$C$27,$S$4),1,INDEX(회차설정!$D$13:$D$27,$S$4)-INDEX(회차설정!$C$13:$C$27,$S$4)+1))) | F14: =IF(OR($S$4="",$D14=0,$D14="",$E14=""),"",$E14/$D14*100) | H14: =IF($F14="","",REPT("■",ROUND($F14/5,0))) | S14: =IF($R$4="","",IFERROR(IF($R$4="언어와 매체",MATCH(12,회차설정!$G$13:$G$27,0),MATCH(12,회차설정!$F$13:$F$27,0)),""))
A15: =IF($S$5="","",INDEX(회차설정!$A$13:$A$27,$S$5)) | B15: =IF($S$5="","",INDEX(회차설정!$B$13:$B$27,$S$5)) | D15: =IF($S$5="","",IF($R$4="언어와 매체",SUMPRODUCT((자동계산!$A$4:$A$48>=INDEX(회차설정!$C$13:$C$27,$S$5))*(자동계산!$A$4:$A$48<=INDEX(회차설정!$D$13:$D$27,$S$5))*자동계산!$E$4:$E$48),SUMPRODUCT((자동계산!$A$4:$A$48>=INDEX(회차설정!$C$13:$C$27,$S$5))*(자동계산!$A$4:$A$48<=INDEX(회차설정!$D$13:$D$27,$S$5))*자동계산!$C$4:$C$48))) | E15: =IF(OR($S$5="",$R$3=""),"",SUM(OFFSET(전체채점!$AW$2,$R$3,INDEX(회차설정!$C$13:$C$27,$S$5),1,INDEX(회차설정!$D$13:$D$27,$S$5)-INDEX(회차설정!$C$13:$C$27,$S$5)+1))) | F15: =IF(OR($S$5="",$D15=0,$D15="",$E15=""),"",$E15/$D15*100) | H15: =IF($F15="","",REPT("■",ROUND($F15/5,0)))
A16: =IF($S$6="","",INDEX(회차설정!$A$13:$A$27,$S$6)) | B16: =IF($S$6="","",INDEX(회차설정!$B$13:$B$27,$S$6)) | D16: =IF($S$6="","",IF($R$4="언어와 매체",SUMPRODUCT((자동계산!$A$4:$A$48>=INDEX(회차설정!$C$13:$C$27,$S$6))*(자동계산!$A$4:$A$48<=INDEX(회차설정!$D$13:$D$27,$S$6))*자동계산!$E$4:$E$48),SUMPRODUCT((자동계산!$A$4:$A$48>=INDEX(회차설정!$C$13:$C$27,$S$6))*(자동계산!$A$4:$A$48<=INDEX(회차설정!$D$13:$D$27,$S$6))*자동계산!$C$4:$C$48))) | E16: =IF(OR($S$6="",$R$3=""),"",SUM(OFFSET(전체채점!$AW$2,$R$3,INDEX(회차설정!$C$13:$C$27,$S$6),1,INDEX(회차설정!$D$13:$D$27,$S$6)-INDEX(회차설정!$C$13:$C$27,$S$6)+1))) | F16: =IF(OR($S$6="",$D16=0,$D16="",$E16=""),"",$E16/$D16*100) | H16: =IF($F16="","",REPT("■",ROUND($F16/5,0)))
A17: =IF($S$7="","",INDEX(회차설정!$A$13:$A$27,$S$7)) | B17: =IF($S$7="","",INDEX(회차설정!$B$13:$B$27,$S$7)) | D17: =IF($S$7="","",IF($R$4="언어와 매체",SUMPRODUCT((자동계산!$A$4:$A$48>=INDEX(회차설정!$C$13:$C$27,$S$7))*(자동계산!$A$4:$A$48<=INDEX(회차설정!$D$13:$D$27,$S$7))*자동계산!$E$4:$E$48),SUMPRODUCT((자동계산!$A$4:$A$48>=INDEX(회차설정!$C$13:$C$27,$S$7))*(자동계산!$A$4:$A$48<=INDEX(회차설정!$D$13:$D$27,$S$7))*자동계산!$C$4:$C$48))) | E17: =IF(OR($S$7="",$R$3=""),"",SUM(OFFSET(전체채점!$AW$2,$R$3,INDEX(회차설정!$C$13:$C$27,$S$7),1,INDEX(회차설정!$D$13:$D$27,$S$7)-INDEX(회차설정!$C$13:$C$27,$S$7)+1))) | F17: =IF(OR($S$7="",$D17=0,$D17="",$E17=""),"",$E17/$D17*100) | H17: =IF($F17="","",REPT("■",ROUND($F17/5,0)))
A18: =IF($S$8="","",INDEX(회차설정!$A$13:$A$27,$S$8)) | B18: =IF($S$8="","",INDEX(회차설정!$B$13:$B$27,$S$8)) | D18: =IF($S$8="","",IF($R$4="언어와 매체",SUMPRODUCT((자동계산!$A$4:$A$48>=INDEX(회차설정!$C$13:$C$27,$S$8))*(자동계산!$A$4:$A$48<=INDEX(회차설정!$D$13:$D$27,$S$8))*자동계산!$E$4:$E$48),SUMPRODUCT((자동계산!$A$4:$A$48>=INDEX(회차설정!$C$13:$C$27,$S$8))*(자동계산!$A$4:$A$48<=INDEX(회차설정!$D$13:$D$27,$S$8))*자동계산!$C$4:$C$48))) | E18: =IF(OR($S$8="",$R$3=""),"",SUM(OFFSET(전체채점!$AW$2,$R$3,INDEX(회차설정!$C$13:$C$27,$S$8),1,INDEX(회차설정!$D$13:$D$27,$S$8)-INDEX(회차설정!$C$13:$C$27,$S$8)+1))) | F18: =IF(OR($S$8="",$D18=0,$D18="",$E18=""),"",$E18/$D18*100) | H18: =IF($F18="","",REPT("■",ROUND($F18/5,0)))
A19: =IF($S$9="","",INDEX(회차설정!$A$13:$A$27,$S$9)) | B19: =IF($S$9="","",INDEX(회차설정!$B$13:$B$27,$S$9)) | D19: =IF($S$9="","",IF($R$4="언어와 매체",SUMPRODUCT((자동계산!$A$4:$A$48>=INDEX(회차설정!$C$13:$C$27,$S$9))*(자동계산!$A$4:$A$48<=INDEX(회차설정!$D$13:$D$27,$S$9))*자동계산!$E$4:$E$48),SUMPRODUCT((자동계산!$A$4:$A$48>=INDEX(회차설정!$C$13:$C$27,$S$9))*(자동계산!$A$4:$A$48<=INDEX(회차설정!$D$13:$D$27,$S$9))*자동계산!$C$4:$C$48))) | E19: =IF(OR($S$9="",$R$3=""),"",SUM(OFFSET(전체채점!$AW$2,$R$3,INDEX(회차설정!$C$13:$C$27,$S$9),1,INDEX(회차설정!$D$13:$D$27,$S$9)-INDEX(회차설정!$C$13:$C$27,$S$9)+1))) | F19: =IF(OR($S$9="",$D19=0,$D19="",$E19=""),"",$E19/$D19*100) | H19: =IF($F19="","",REPT("■",ROUND($F19/5,0)))
A20: =IF($S$10="","",INDEX(회차설정!$A$13:$A$27,$S$10)) | B20: =IF($S$10="","",INDEX(회차설정!$B$13:$B$27,$S$10)) | D20: =IF($S$10="","",IF($R$4="언어와 매체",SUMPRODUCT((자동계산!$A$4:$A$48>=INDEX(회차설정!$C$13:$C$27,$S$10))*(자동계산!$A$4:$A$48<=INDEX(회차설정!$D$13:$D$27,$S$10))*자동계산!$E$4:$E$48),SUMPRODUCT((자동계산!$A$4:$A$48>=INDEX(회차설정!$C$13:$C$27,$S$10))*(자동계산!$A$4:$A$48<=INDEX(회차설정!$D$13:$D$27,$S$10))*자동계산!$C$4:$C$48))) | E20: =IF(OR($S$10="",$R$3=""),"",SUM(OFFSET(전체채점!$AW$2,$R$3,INDEX(회차설정!$C$13:$C$27,$S$10),1,INDEX(회차설정!$D$13:$D$27,$S$10)-INDEX(회차설정!$C$13:$C$27,$S$10)+1))) | F20: =IF(OR($S$10="",$D20=0,$D20="",$E20=""),"",$E20/$D20*100) | H20: =IF($F20="","",REPT("■",ROUND($F20/5,0)))
A21: =IF($S$11="","",INDEX(회차설정!$A$13:$A$27,$S$11)) | B21: =IF($S$11="","",INDEX(회차설정!$B$13:$B$27,$S$11)) | D21: =IF($S$11="","",IF($R$4="언어와 매체",SUMPRODUCT((자동계산!$A$4:$A$48>=INDEX(회차설정!$C$13:$C$27,$S$11))*(자동계산!$A$4:$A$48<=INDEX(회차설정!$D$13:$D$27,$S$11))*자동계산!$E$4:$E$48),SUMPRODUCT((자동계산!$A$4:$A$48>=INDEX(회차설정!$C$13:$C$27,$S$11))*(자동계산!$A$4:$A$48<=INDEX(회차설정!$D$13:$D$27,$S$11))*자동계산!$C$4:$C$48))) | E21: =IF(OR($S$11="",$R$3=""),"",SUM(OFFSET(전체채점!$AW$2,$R$3,INDEX(회차설정!$C$13:$C$27,$S$11),1,INDEX(회차설정!$D$13:$D$27,$S$11)-INDEX(회차설정!$C$13:$C$27,$S$11)+1))) | F21: =IF(OR($S$11="",$D21=0,$D21="",$E21=""),"",$E21/$D21*100) | H21: =IF($F21="","",REPT("■",ROUND($F21/5,0)))
A22: =IF($S$12="","",INDEX(회차설정!$A$13:$A$27,$S$12)) | B22: =IF($S$12="","",INDEX(회차설정!$B$13:$B$27,$S$12)) | D22: =IF($S$12="","",IF($R$4="언어와 매체",SUMPRODUCT((자동계산!$A$4:$A$48>=INDEX(회차설정!$C$13:$C$27,$S$12))*(자동계산!$A$4:$A$48<=INDEX(회차설정!$D$13:$D$27,$S$12))*자동계산!$E$4:$E$48),SUMPRODUCT((자동계산!$A$4:$A$48>=INDEX(회차설정!$C$13:$C$27,$S$12))*(자동계산!$A$4:$A$48<=INDEX(회차설정!$D$13:$D$27,$S$12))*자동계산!$C$4:$C$48))) | E22: =IF(OR($S$12="",$R$3=""),"",SUM(OFFSET(전체채점!$AW$2,$R$3,INDEX(회차설정!$C$13:$C$27,$S$12),1,INDEX(회차설정!$D$13:$D$27,$S$12)-INDEX(회차설정!$C$13:$C$27,$S$12)+1))) | F22: =IF(OR($S$12="",$D22=0,$D22="",$E22=""),"",$E22/$D22*100) | H22: =IF($F22="","",REPT("■",ROUND($F22/5,0)))
A23: =IF($S$13="","",INDEX(회차설정!$A$13:$A$27,$S$13)) | B23: =IF($S$13="","",INDEX(회차설정!$B$13:$B$27,$S$13)) | D23: =IF($S$13="","",IF($R$4="언어와 매체",SUMPRODUCT((자동계산!$A$4:$A$48>=INDEX(회차설정!$C$13:$C$27,$S$13))*(자동계산!$A$4:$A$48<=INDEX(회차설정!$D$13:$D$27,$S$13))*자동계산!$E$4:$E$48),SUMPRODUCT((자동계산!$A$4:$A$48>=INDEX(회차설정!$C$13:$C$27,$S$13))*(자동계산!$A$4:$A$48<=INDEX(회차설정!$D$13:$D$27,$S$13))*자동계산!$C$4:$C$48))) | E23: =IF(OR($S$13="",$R$3=""),"",SUM(OFFSET(전체채점!$AW$2,$R$3,INDEX(회차설정!$C$13:$C$27,$S$13),1,INDEX(회차설정!$D$13:$D$27,$S$13)-INDEX(회차설정!$C$13:$C$27,$S$13)+1))) | F23: =IF(OR($S$13="",$D23=0,$D23="",$E23=""),"",$E23/$D23*100) | H23: =IF($F23="","",REPT("■",ROUND($F23/5,0)))
A24: =IF($S$14="","",INDEX(회차설정!$A$13:$A$27,$S$14)) | B24: =IF($S$14="","",INDEX(회차설정!$B$13:$B$27,$S$14)) | D24: =IF($S$14="","",IF($R$4="언어와 매체",SUMPRODUCT((자동계산!$A$4:$A$48>=INDEX(회차설정!$C$13:$C$27,$S$14))*(자동계산!$A$4:$A$48<=INDEX(회차설정!$D$13:$D$27,$S$14))*자동계산!$E$4:$E$48),SUMPRODUCT((자동계산!$A$4:$A$48>=INDEX(회차설정!$C$13:$C$27,$S$14))*(자동계산!$A$4:$A$48<=INDEX(회차설정!$D$13:$D$27,$S$14))*자동계산!$C$4:$C$48))) | E24: =IF(OR($S$14="",$R$3=""),"",SUM(OFFSET(전체채점!$AW$2,$R$3,INDEX(회차설정!$C$13:$C$27,$S$14),1,INDEX(회차설정!$D$13:$D$27,$S$14)-INDEX(회차설정!$C$13:$C$27,$S$14)+1))) | F24: =IF(OR($S$14="",$D24=0,$D24="",$E24=""),"",$E24/$D24*100) | H24: =IF($F24="","",REPT("■",ROUND($F24/5,0)))
A25: =IF($R$3="","","합계") | D25: =IF($R$3="","",SUM(D13:D24)) | E25: =IF($R$3="","",SUM(E13:E24)) | F25: =IF(OR($D25=0,$D25=""),"",$E25/$D25*100) | H25: =IF($F25="","",REPT("■",ROUND($F25/5,0)))
A27: 4. 문항 채점표
A28: 문항 번호 | B28: 1 | C28: 2 | D28: 3 | E28: 4 | F28: 5 | G28: 6 | H28: 7 | I28: 8 | J28: 9 | K28: 10 | L28: 11 | M28: 12 | N28: 13 | O28: 14 | P28: 15
A29: 정답 | B29: =IF($R$4="","",IF($R$4="언어와 매체",자동계산!$D$4,자동계산!$B$4)) | C29: =IF($R$4="","",IF($R$4="언어와 매체",자동계산!$D$5,자동계산!$B$5)) | D29: =IF($R$4="","",IF($R$4="언어와 매체",자동계산!$D$6,자동계산!$B$6)) | E29: =IF($R$4="","",IF($R$4="언어와 매체",자동계산!$D$7,자동계산!$B$7)) | F29: =IF($R$4="","",IF($R$4="언어와 매체",자동계산!$D$8,자동계산!$B$8)) | G29: =IF($R$4="","",IF($R$4="언어와 매체",자동계산!$D$9,자동계산!$B$9)) | H29: =IF($R$4="","",IF($R$4="언어와 매체",자동계산!$D$10,자동계산!$B$10)) | I29: =IF($R$4="","",IF($R$4="언어와 매체",자동계산!$D$11,자동계산!$B$11)) | J29: =IF($R$4="","",IF($R$4="언어와 매체",자동계산!$D$12,자동계산!$B$12)) | K29: =IF($R$4="","",IF($R$4="언어와 매체",자동계산!$D$13,자동계산!$B$13)) | L29: =IF($R$4="","",IF($R$4="언어와 매체",자동계산!$D$14,자동계산!$B$14)) | M29: =IF($R$4="","",IF($R$4="언어와 매체",자동계산!$D$15,자동계산!$B$15)) | N29: =IF($R$4="","",IF($R$4="언어와 매체",자동계산!$D$16,자동계산!$B$16)) | O29: =IF($R$4="","",IF($R$4="언어와 매체",자동계산!$D$17,자동계산!$B$17)) | P29: =IF($R$4="","",IF($R$4="언어와 매체",자동계산!$D$18,자동계산!$B$18))
A30: 학생답안 | B30: =IF($R$3="","",INDEX(전체채점!E$3:E$62,$R$3)) | C30: =IF($R$3="","",INDEX(전체채점!F$3:F$62,$R$3)) | D30: =IF($R$3="","",INDEX(전체채점!G$3:G$62,$R$3)) | E30: =IF($R$3="","",INDEX(전체채점!H$3:H$62,$R$3)) | F30: =IF($R$3="","",INDEX(전체채점!I$3:I$62,$R$3)) | G30: =IF($R$3="","",INDEX(전체채점!J$3:J$62,$R$3)) | H30: =IF($R$3="","",INDEX(전체채점!K$3:K$62,$R$3)) | I30: =IF($R$3="","",INDEX(전체채점!L$3:L$62,$R$3)) | ... P30: =IF($R$3="","",INDEX(전체채점!S$3:S$62,$R$3))
A31: 정오 | B31: =IF($R$3="","",INDEX(전체채점!AX$3:AX$62,$R$3)) | C31: =IF($R$3="","",INDEX(전체채점!AY$3:AY$62,$R$3)) | D31: =IF($R$3="","",INDEX(전체채점!AZ$3:AZ$62,$R$3)) | E31: =IF($R$3="","",INDEX(전체채점!BA$3:BA$62,$R$3)) | F31: =IF($R$3="","",INDEX(전체채점!BB$3:BB$62,$R$3)) | G31: =IF($R$3="","",INDEX(전체채점!BC$3:BC$62,$R$3)) | H31: =IF($R$3="","",INDEX(전체채점!BD$3:BD$62,$R$3)) | I31: =IF($R$3="","",INDEX(전체채점!BE$3:BE$62,$R$3)) | ... P31: =IF($R$3="","",INDEX(전체채점!BL$3:BL$62,$R$3))
A32: 문항 번호 | B32: 16 | C32: 17 | D32: 18 | E32: 19 | F32: 20 | G32: 21 | H32: 22 | I32: 23 | J32: 24 | K32: 25 | L32: 26 | M32: 27 | N32: 28 | O32: 29 | P32: 30
A33: 정답 | B33: =IF($R$4="","",IF($R$4="언어와 매체",자동계산!$D$19,자동계산!$B$19)) | C33: =IF($R$4="","",IF($R$4="언어와 매체",자동계산!$D$20,자동계산!$B$20)) | D33: =IF($R$4="","",IF($R$4="언어와 매체",자동계산!$D$21,자동계산!$B$21)) | E33: =IF($R$4="","",IF($R$4="언어와 매체",자동계산!$D$22,자동계산!$B$22)) | F33: =IF($R$4="","",IF($R$4="언어와 매체",자동계산!$D$23,자동계산!$B$23)) | G33: =IF($R$4="","",IF($R$4="언어와 매체",자동계산!$D$24,자동계산!$B$24)) | H33: =IF($R$4="","",IF($R$4="언어와 매체",자동계산!$D$25,자동계산!$B$25)) | I33: =IF($R$4="","",IF($R$4="언어와 매체",자동계산!$D$26,자동계산!$B$26)) | J33: =IF($R$4="","",IF($R$4="언어와 매체",자동계산!$D$27,자동계산!$B$27)) | K33: =IF($R$4="","",IF($R$4="언어와 매체",자동계산!$D$28,자동계산!$B$28)) | L33: =IF($R$4="","",IF($R$4="언어와 매체",자동계산!$D$29,자동계산!$B$29)) | M33: =IF($R$4="","",IF($R$4="언어와 매체",자동계산!$D$30,자동계산!$B$30)) | N33: =IF($R$4="","",IF($R$4="언어와 매체",자동계산!$D$31,자동계산!$B$31)) | O33: =IF($R$4="","",IF($R$4="언어와 매체",자동계산!$D$32,자동계산!$B$32)) | P33: =IF($R$4="","",IF($R$4="언어와 매체",자동계산!$D$33,자동계산!$B$33))
A34: 학생답안 | B34: =IF($R$3="","",INDEX(전체채점!T$3:T$62,$R$3)) | C34: =IF($R$3="","",INDEX(전체채점!U$3:U$62,$R$3)) | D34: =IF($R$3="","",INDEX(전체채점!V$3:V$62,$R$3)) | E34: =IF($R$3="","",INDEX(전체채점!W$3:W$62,$R$3)) | F34: =IF($R$3="","",INDEX(전체채점!X$3:X$62,$R$3)) | G34: =IF($R$3="","",INDEX(전체채점!Y$3:Y$62,$R$3)) | H34: =IF($R$3="","",INDEX(전체채점!Z$3:Z$62,$R$3)) | I34: =IF($R$3="","",INDEX(전체채점!AA$3:AA$62,$R$3)) | ... P34: =IF($R$3="","",INDEX(전체채점!AH$3:AH$62,$R$3))
A35: 정오 | B35: =IF($R$3="","",INDEX(전체채점!BM$3:BM$62,$R$3)) | C35: =IF($R$3="","",INDEX(전체채점!BN$3:BN$62,$R$3)) | D35: =IF($R$3="","",INDEX(전체채점!BO$3:BO$62,$R$3)) | E35: =IF($R$3="","",INDEX(전체채점!BP$3:BP$62,$R$3)) | F35: =IF($R$3="","",INDEX(전체채점!BQ$3:BQ$62,$R$3)) | G35: =IF($R$3="","",INDEX(전체채점!BR$3:BR$62,$R$3)) | H35: =IF($R$3="","",INDEX(전체채점!BS$3:BS$62,$R$3)) | I35: =IF($R$3="","",INDEX(전체채점!BT$3:BT$62,$R$3)) | ... P35: =IF($R$3="","",INDEX(전체채점!CA$3:CA$62,$R$3))
A36: 문항 번호 | B36: 31 | C36: 32 | D36: 33 | E36: 34 | F36: 35 | G36: 36 | H36: 37 | I36: 38 | J36: 39 | K36: 40 | L36: 41 | M36: 42 | N36: 43 | O36: 44 | P36: 45
A37: 정답 | B37: =IF($R$4="","",IF($R$4="언어와 매체",자동계산!$D$34,자동계산!$B$34)) | C37: =IF($R$4="","",IF($R$4="언어와 매체",자동계산!$D$35,자동계산!$B$35)) | D37: =IF($R$4="","",IF($R$4="언어와 매체",자동계산!$D$36,자동계산!$B$36)) | E37: =IF($R$4="","",IF($R$4="언어와 매체",자동계산!$D$37,자동계산!$B$37)) | F37: =IF($R$4="","",IF($R$4="언어와 매체",자동계산!$D$38,자동계산!$B$38)) | G37: =IF($R$4="","",IF($R$4="언어와 매체",자동계산!$D$39,자동계산!$B$39)) | H37: =IF($R$4="","",IF($R$4="언어와 매체",자동계산!$D$40,자동계산!$B$40)) | I37: =IF($R$4="","",IF($R$4="언어와 매체",자동계산!$D$41,자동계산!$B$41)) | J37: =IF($R$4="","",IF($R$4="언어와 매체",자동계산!$D$42,자동계산!$B$42)) | K37: =IF($R$4="","",IF($R$4="언어와 매체",자동계산!$D$43,자동계산!$B$43)) | L37: =IF($R$4="","",IF($R$4="언어와 매체",자동계산!$D$44,자동계산!$B$44)) | M37: =IF($R$4="","",IF($R$4="언어와 매체",자동계산!$D$45,자동계산!$B$45)) | N37: =IF($R$4="","",IF($R$4="언어와 매체",자동계산!$D$46,자동계산!$B$46)) | O37: =IF($R$4="","",IF($R$4="언어와 매체",자동계산!$D$47,자동계산!$B$47)) | P37: =IF($R$4="","",IF($R$4="언어와 매체",자동계산!$D$48,자동계산!$B$48))
A38: 학생답안 | B38: =IF($R$3="","",INDEX(전체채점!AI$3:AI$62,$R$3)) | C38: =IF($R$3="","",INDEX(전체채점!AJ$3:AJ$62,$R$3)) | D38: =IF($R$3="","",INDEX(전체채점!AK$3:AK$62,$R$3)) | E38: =IF($R$3="","",INDEX(전체채점!AL$3:AL$62,$R$3)) | F38: =IF($R$3="","",INDEX(전체채점!AM$3:AM$62,$R$3)) | G38: =IF($R$3="","",INDEX(전체채점!AN$3:AN$62,$R$3)) | H38: =IF($R$3="","",INDEX(전체채점!AO$3:AO$62,$R$3)) | I38: =IF($R$3="","",INDEX(전체채점!AP$3:AP$62,$R$3)) | ... P38: =IF($R$3="","",INDEX(전체채점!AW$3:AW$62,$R$3))
A39: 정오 | B39: =IF($R$3="","",INDEX(전체채점!CB$3:CB$62,$R$3)) | C39: =IF($R$3="","",INDEX(전체채점!CC$3:CC$62,$R$3)) | D39: =IF($R$3="","",INDEX(전체채점!CD$3:CD$62,$R$3)) | E39: =IF($R$3="","",INDEX(전체채점!CE$3:CE$62,$R$3)) | F39: =IF($R$3="","",INDEX(전체채점!CF$3:CF$62,$R$3)) | G39: =IF($R$3="","",INDEX(전체채점!CG$3:CG$62,$R$3)) | H39: =IF($R$3="","",INDEX(전체채점!CH$3:CH$62,$R$3)) | I39: =IF($R$3="","",INDEX(전체채점!CI$3:CI$62,$R$3)) | ... P39: =IF($R$3="","",INDEX(전체채점!CP$3:CP$62,$R$3))
A41: ※ 위 노란 칸(성명)을 누르면 학생 목록이 펼쳐집니다. 고르면 성적표가 그 학생 것으로 바뀝니다.

Sheet 성적표(전원)
A1: =IF($R$3="","",회차설정!$B$2&" 성적표")
A3: 1. 학생정보 | R3: =IF(답안입력!$A$3="","",1) | S3: =IF($R$4="","",IFERROR(IF($R$4="언어와 매체",MATCH(1,회차설정!$G$13:$G$27,0),MATCH(1,회차설정!$F$13:$F$27,0)),""))
A4: 성명 | D4: 선택과목 | H4: 학년 | L4: 시행일 | R4: =IF($R$3="","",INDEX(전체채점!$B$3:$B$62,$R$3)) | S4: =IF($R$4="","",IFERROR(IF($R$4="언어와 매체",MATCH(2,회차설정!$G$13:$G$27,0),MATCH(2,회차설정!$F$13:$F$27,0)),""))
A5: =IF($R$3="","",INDEX(답안입력!$A$3:$A$62,$R$3)) | D5: =IF($R$3="","",INDEX(답안입력!$C$3:$C$62,$R$3)) | H5: =IF($R$3="","",INDEX(답안입력!$B$3:$B$62,$R$3)) | L5: =회차설정!$B$3 | R5: =IF($R$4="언어와 매체",회차설정!$B$9,회차설정!$B$8) | S5: =IF($R$4="","",IFERROR(IF($R$4="언어와 매체",MATCH(3,회차설정!$G$13:$G$27,0),MATCH(3,회차설정!$F$13:$F$27,0)),""))
R6: =IF($R$4="언어와 매체",회차설정!$C$9,회차설정!$C$8) | S6: =IF($R$4="","",IFERROR(IF($R$4="언어와 매체",MATCH(4,회차설정!$G$13:$G$27,0),MATCH(4,회차설정!$F$13:$F$27,0)),""))
A7: 2. 성적 | R7: =IF($R$4="언어와 매체",회차설정!$D$9,회차설정!$D$8) | S7: =IF($R$4="","",IFERROR(IF($R$4="언어와 매체",MATCH(5,회차설정!$G$13:$G$27,0),MATCH(5,회차설정!$F$13:$F$27,0)),""))
A8: 점수 (100점 만점) | F8: 등급 | I8: 등급컷 | M8: 같은 선택과목 평균 | R8: =IF($R$4="언어와 매체",회차설정!$E$9,회차설정!$E$8) | S8: =IF($R$4="","",IFERROR(IF($R$4="언어와 매체",MATCH(6,회차설정!$G$13:$G$27,0),MATCH(6,회차설정!$F$13:$F$27,0)),""))
A9: =IF($R$3="","",INDEX(전체채점!$C$3:$C$62,$R$3)) | F9: =IF($R$3="","",INDEX(전체채점!$D$3:$D$62,$R$3)) | I9: =IF($R$3="","",$R$5&"-"&$R$6&"-"&$R$7&"-"&$R$8) | M9: =IFERROR(AVERAGEIF(전체채점!$B$3:$B$62,$R$4,전체채점!$C$3:$C$62),"") | S9: =IF($R$4="","",IFERROR(IF($R$4="언어와 매체",MATCH(7,회차설정!$G$13:$G$27,0),MATCH(7,회차설정!$F$13:$F$27,0)),""))
S10: =IF($R$4="","",IFERROR(IF($R$4="언어와 매체",MATCH(8,회차설정!$G$13:$G$27,0),MATCH(8,회차설정!$F$13:$F$27,0)),""))
A11: 3. 영역분류별 성취도 분석 | F11: =IF(OR($R$3="",$E25=""),"",IF($E25=INDEX(전체채점!$C$3:$C$62,$R$3),"","※ 회차설정의 영역 표를 확인하세요 — 영역 합계와 점수가 다릅니다")) | S11: =IF($R$4="","",IFERROR(IF($R$4="언어와 매체",MATCH(9,회차설정!$G$13:$G$27,0),MATCH(9,회차설정!$F$13:$F$27,0)),""))
A12: 분류 | B12: 영역 | D12: 배점 | E12: 득점 | F12: 성취도(%) | S12: =IF($R$4="","",IFERROR(IF($R$4="언어와 매체",MATCH(10,회차설정!$G$13:$G$27,0),MATCH(10,회차설정!$F$13:$F$27,0)),""))
A13: =IF($S$3="","",INDEX(회차설정!$A$13:$A$27,$S$3)) | B13: =IF($S$3="","",INDEX(회차설정!$B$13:$B$27,$S$3)) | D13: =IF($S$3="","",IF($R$4="언어와 매체",SUMPRODUCT((자동계산!$A$4:$A$48>=INDEX(회차설정!$C$13:$C$27,$S$3))*(자동계산!$A$4:$A$48<=INDEX(회차설정!$D$13:$D$27,$S$3))*자동계산!$E$4:$E$48),SUMPRODUCT((자동계산!$A$4:$A$48>=INDEX(회차설정!$C$13:$C$27,$S$3))*(자동계산!$A$4:$A$48<=INDEX(회차설정!$D$13:$D$27,$S$3))*자동계산!$C$4:$C$48))) | E13: =IF(OR($S$3="",$R$3=""),"",SUM(OFFSET(전체채점!$AW$2,$R$3,INDEX(회차설정!$C$13:$C$27,$S$3),1,INDEX(회차설정!$D$13:$D$27,$S$3)-INDEX(회차설정!$C$13:$C$27,$S$3)+1))) | F13: =IF(OR($S$3="",$D13=0,$D13="",$E13=""),"",$E13/$D13*100) | H13: =IF($F13="","",REPT("■",ROUND($F13/5,0))) | S13: =IF($R$4="","",IFERROR(IF($R$4="언어와 매체",MATCH(11,회차설정!$G$13:$G$27,0),MATCH(11,회차설정!$F$13:$F$27,0)),""))
A14: =IF($S$4="","",INDEX(회차설정!$A$13:$A$27,$S$4)) | B14: =IF($S$4="","",INDEX(회차설정!$B$13:$B$27,$S$4)) | D14: =IF($S$4="","",IF($R$4="언어와 매체",SUMPRODUCT((자동계산!$A$4:$A$48>=INDEX(회차설정!$C$13:$C$27,$S$4))*(자동계산!$A$4:$A$48<=INDEX(회차설정!$D$13:$D$27,$S$4))*자동계산!$E$4:$E$48),SUMPRODUCT((자동계산!$A$4:$A$48>=INDEX(회차설정!$C$13:$C$27,$S$4))*(자동계산!$A$4:$A$48<=INDEX(회차설정!$D$13:$D$27,$S$4))*자동계산!$C$4:$C$48))) | E14: =IF(OR($S$4="",$R$3=""),"",SUM(OFFSET(전체채점!$AW$2,$R$3,INDEX(회차설정!$C$13:$C$27,$S$4),1,INDEX(회차설정!$D$13:$D$27,$S$4)-INDEX(회차설정!$C$13:$C$27,$S$4)+1))) | F14: =IF(OR($S$4="",$D14=0,$D14="",$E14=""),"",$E14/$D14*100) | H14: =IF($F14="","",REPT("■",ROUND($F14/5,0))) | S14: =IF($R$4="","",IFERROR(IF($R$4="언어와 매체",MATCH(12,회차설정!$G$13:$G$27,0),MATCH(12,회차설정!$F$13:$F$27,0)),""))
A15: =IF($S$5="","",INDEX(회차설정!$A$13:$A$27,$S$5)) | B15: =IF($S$5="","",INDEX(회차설정!$B$13:$B$27,$S$5)) | D15: =IF($S$5="","",IF($R$4="언어와 매체",SUMPRODUCT((자동계산!$A$4:$A$48>=INDEX(회차설정!$C$13:$C$27,$S$5))*(자동계산!$A$4:$A$48<=INDEX(회차설정!$D$13:$D$27,$S$5))*자동계산!$E$4:$E$48),SUMPRODUCT((자동계산!$A$4:$A$48>=INDEX(회차설정!$C$13:$C$27,$S$5))*(자동계산!$A$4:$A$48<=INDEX(회차설정!$D$13:$D$27,$S$5))*자동계산!$C$4:$C$48))) | E15: =IF(OR($S$5="",$R$3=""),"",SUM(OFFSET(전체채점!$AW$2,$R$3,INDEX(회차설정!$C$13:$C$27,$S$5),1,INDEX(회차설정!$D$13:$D$27,$S$5)-INDEX(회차설정!$C$13:$C$27,$S$5)+1))) | F15: =IF(OR($S$5="",$D15=0,$D15="",$E15=""),"",$E15/$D15*100) | H15: =IF($F15="","",REPT("■",ROUND($F15/5,0)))
A16: =IF($S$6="","",INDEX(회차설정!$A$13:$A$27,$S$6)) | B16: =IF($S$6="","",INDEX(회차설정!$B$13:$B$27,$S$6)) | D16: =IF($S$6="","",IF($R$4="언어와 매체",SUMPRODUCT((자동계산!$A$4:$A$48>=INDEX(회차설정!$C$13:$C$27,$S$6))*(자동계산!$A$4:$A$48<=INDEX(회차설정!$D$13:$D$27,$S$6))*자동계산!$E$4:$E$48),SUMPRODUCT((자동계산!$A$4:$A$48>=INDEX(회차설정!$C$13:$C$27,$S$6))*(자동계산!$A$4:$A$48<=INDEX(회차설정!$D$13:$D$27,$S$6))*자동계산!$C$4:$C$48))) | E16: =IF(OR($S$6="",$R$3=""),"",SUM(OFFSET(전체채점!$AW$2,$R$3,INDEX(회차설정!$C$13:$C$27,$S$6),1,INDEX(회차설정!$D$13:$D$27,$S$6)-INDEX(회차설정!$C$13:$C$27,$S$6)+1))) | F16: =IF(OR($S$6="",$D16=0,$D16="",$E16=""),"",$E16/$D16*100) | H16: =IF($F16="","",REPT("■",ROUND($F16/5,0)))
A17: =IF($S$7="","",INDEX(회차설정!$A$13:$A$27,$S$7)) | B17: =IF($S$7="","",INDEX(회차설정!$B$13:$B$27,$S$7)) | D17: =IF($S$7="","",IF($R$4="언어와 매체",SUMPRODUCT((자동계산!$A$4:$A$48>=INDEX(회차설정!$C$13:$C$27,$S$7))*(자동계산!$A$4:$A$48<=INDEX(회차설정!$D$13:$D$27,$S$7))*자동계산!$E$4:$E$48),SUMPRODUCT((자동계산!$A$4:$A$48>=INDEX(회차설정!$C$13:$C$27,$S$7))*(자동계산!$A$4:$A$48<=INDEX(회차설정!$D$13:$D$27,$S$7))*자동계산!$C$4:$C$48))) | E17: =IF(OR($S$7="",$R$3=""),"",SUM(OFFSET(전체채점!$AW$2,$R$3,INDEX(회차설정!$C$13:$C$27,$S$7),1,INDEX(회차설정!$D$13:$D$27,$S$7)-INDEX(회차설정!$C$13:$C$27,$S$7)+1))) | F17: =IF(OR($S$7="",$D17=0,$D17="",$E17=""),"",$E17/$D17*100) | H17: =IF($F17="","",REPT("■",ROUND($F17/5,0)))
A18: =IF($S$8="","",INDEX(회차설정!$A$13:$A$27,$S$8)) | B18: =IF($S$8="","",INDEX(회차설정!$B$13:$B$27,$S$8)) | D18: =IF($S$8="","",IF($R$4="언어와 매체",SUMPRODUCT((자동계산!$A$4:$A$48>=INDEX(회차설정!$C$13:$C$27,$S$8))*(자동계산!$A$4:$A$48<=INDEX(회차설정!$D$13:$D$27,$S$8))*자동계산!$E$4:$E$48),SUMPRODUCT((자동계산!$A$4:$A$48>=INDEX(회차설정!$C$13:$C$27,$S$8))*(자동계산!$A$4:$A$48<=INDEX(회차설정!$D$13:$D$27,$S$8))*자동계산!$C$4:$C$48))) | E18: =IF(OR($S$8="",$R$3=""),"",SUM(OFFSET(전체채점!$AW$2,$R$3,INDEX(회차설정!$C$13:$C$27,$S$8),1,INDEX(회차설정!$D$13:$D$27,$S$8)-INDEX(회차설정!$C$13:$C$27,$S$8)+1))) | F18: =IF(OR($S$8="",$D18=0,$D18="",$E18=""),"",$E18/$D18*100) | H18: =IF($F18="","",REPT("■",ROUND($F18/5,0)))
A19: =IF($S$9="","",INDEX(회차설정!$A$13:$A$27,$S$9)) | B19: =IF($S$9="","",INDEX(회차설정!$B$13:$B$27,$S$9)) | D19: =IF($S$9="","",IF($R$4="언어와 매체",SUMPRODUCT((자동계산!$A$4:$A$48>=INDEX(회차설정!$C$13:$C$27,$S$9))*(자동계산!$A$4:$A$48<=INDEX(회차설정!$D$13:$D$27,$S$9))*자동계산!$E$4:$E$48),SUMPRODUCT((자동계산!$A$4:$A$48>=INDEX(회차설정!$C$13:$C$27,$S$9))*(자동계산!$A$4:$A$48<=INDEX(회차설정!$D$13:$D$27,$S$9))*자동계산!$C$4:$C$48))) | E19: =IF(OR($S$9="",$R$3=""),"",SUM(OFFSET(전체채점!$AW$2,$R$3,INDEX(회차설정!$C$13:$C$27,$S$9),1,INDEX(회차설정!$D$13:$D$27,$S$9)-INDEX(회차설정!$C$13:$C$27,$S$9)+1))) | F19: =IF(OR($S$9="",$D19=0,$D19="",$E19=""),"",$E19/$D19*100) | H19: =IF($F19="","",REPT("■",ROUND($F19/5,0)))
A20: =IF($S$10="","",INDEX(회차설정!$A$13:$A$27,$S$10)) | B20: =IF($S$10="","",INDEX(회차설정!$B$13:$B$27,$S$10)) | D20: =IF($S$10="","",IF($R$4="언어와 매체",SUMPRODUCT((자동계산!$A$4:$A$48>=INDEX(회차설정!$C$13:$C$27,$S$10))*(자동계산!$A$4:$A$48<=INDEX(회차설정!$D$13:$D$27,$S$10))*자동계산!$E$4:$E$48),SUMPRODUCT((자동계산!$A$4:$A$48>=INDEX(회차설정!$C$13:$C$27,$S$10))*(자동계산!$A$4:$A$48<=INDEX(회차설정!$D$13:$D$27,$S$10))*자동계산!$C$4:$C$48))) | E20: =IF(OR($S$10="",$R$3=""),"",SUM(OFFSET(전체채점!$AW$2,$R$3,INDEX(회차설정!$C$13:$C$27,$S$10),1,INDEX(회차설정!$D$13:$D$27,$S$10)-INDEX(회차설정!$C$13:$C$27,$S$10)+1))) | F20: =IF(OR($S$10="",$D20=0,$D20="",$E20=""),"",$E20/$D20*100) | H20: =IF($F20="","",REPT("■",ROUND($F20/5,0)))
A21: =IF($S$11="","",INDEX(회차설정!$A$13:$A$27,$S$11)) | B21: =IF($S$11="","",INDEX(회차설정!$B$13:$B$27,$S$11)) | D21: =IF($S$11="","",IF($R$4="언어와 매체",SUMPRODUCT((자동계산!$A$4:$A$48>=INDEX(회차설정!$C$13:$C$27,$S$11))*(자동계산!$A$4:$A$48<=INDEX(회차설정!$D$13:$D$27,$S$11))*자동계산!$E$4:$E$48),SUMPRODUCT((자동계산!$A$4:$A$48>=INDEX(회차설정!$C$13:$C$27,$S$11))*(자동계산!$A$4:$A$48<=INDEX(회차설정!$D$13:$D$27,$S$11))*자동계산!$C$4:$C$48))) | E21: =IF(OR($S$11="",$R$3=""),"",SUM(OFFSET(전체채점!$AW$2,$R$3,INDEX(회차설정!$C$13:$C$27,$S$11),1,INDEX(회차설정!$D$13:$D$27,$S$11)-INDEX(회차설정!$C$13:$C$27,$S$11)+1))) | F21: =IF(OR($S$11="",$D21=0,$D21="",$E21=""),"",$E21/$D21*100) | H21: =IF($F21="","",REPT("■",ROUND($F21/5,0)))
A22: =IF($S$12="","",INDEX(회차설정!$A$13:$A$27,$S$12)) | B22: =IF($S$12="","",INDEX(회차설정!$B$13:$B$27,$S$12)) | D22: =IF($S$12="","",IF($R$4="언어와 매체",SUMPRODUCT((자동계산!$A$4:$A$48>=INDEX(회차설정!$C$13:$C$27,$S$12))*(자동계산!$A$4:$A$48<=INDEX(회차설정!$D$13:$D$27,$S$12))*자동계산!$E$4:$E$48),SUMPRODUCT((자동계산!$A$4:$A$48>=INDEX(회차설정!$C$13:$C$27,$S$12))*(자동계산!$A$4:$A$48<=INDEX(회차설정!$D$13:$D$27,$S$12))*자동계산!$C$4:$C$48))) | E22: =IF(OR($S$12="",$R$3=""),"",SUM(OFFSET(전체채점!$AW$2,$R$3,INDEX(회차설정!$C$13:$C$27,$S$12),1,INDEX(회차설정!$D$13:$D$27,$S$12)-INDEX(회차설정!$C$13:$C$27,$S$12)+1))) | F22: =IF(OR($S$12="",$D22=0,$D22="",$E22=""),"",$E22/$D22*100) | H22: =IF($F22="","",REPT("■",ROUND($F22/5,0)))
A23: =IF($S$13="","",INDEX(회차설정!$A$13:$A$27,$S$13)) | B23: =IF($S$13="","",INDEX(회차설정!$B$13:$B$27,$S$13)) | D23: =IF($S$13="","",IF($R$4="언어와 매체",SUMPRODUCT((자동계산!$A$4:$A$48>=INDEX(회차설정!$C$13:$C$27,$S$13))*(자동계산!$A$4:$A$48<=INDEX(회차설정!$D$13:$D$27,$S$13))*자동계산!$E$4:$E$48),SUMPRODUCT((자동계산!$A$4:$A$48>=INDEX(회차설정!$C$13:$C$27,$S$13))*(자동계산!$A$4:$A$48<=INDEX(회차설정!$D$13:$D$27,$S$13))*자동계산!$C$4:$C$48))) | E23: =IF(OR($S$13="",$R$3=""),"",SUM(OFFSET(전체채점!$AW$2,$R$3,INDEX(회차설정!$C$13:$C$27,$S$13),1,INDEX(회차설정!$D$13:$D$27,$S$13)-INDEX(회차설정!$C$13:$C$27,$S$13)+1))) | F23: =IF(OR($S$13="",$D23=0,$D23="",$E23=""),"",$E23/$D23*100) | H23: =IF($F23="","",REPT("■",ROUND($F23/5,0)))
A24: =IF($S$14="","",INDEX(회차설정!$A$13:$A$27,$S$14)) | B24: =IF($S$14="","",INDEX(회차설정!$B$13:$B$27,$S$14)) | D24: =IF($S$14="","",IF($R$4="언어와 매체",SUMPRODUCT((자동계산!$A$4:$A$48>=INDEX(회차설정!$C$13:$C$27,$S$14))*(자동계산!$A$4:$A$48<=INDEX(회차설정!$D$13:$D$27,$S$14))*자동계산!$E$4:$E$48),SUMPRODUCT((자동계산!$A$4:$A$48>=INDEX(회차설정!$C$13:$C$27,$S$14))*(자동계산!$A$4:$A$48<=INDEX(회차설정!$D$13:$D$27,$S$14))*자동계산!$C$4:$C$48))) | E24: =IF(OR($S$14="",$R$3=""),"",SUM(OFFSET(전체채점!$AW$2,$R$3,INDEX(회차설정!$C$13:$C$27,$S$14),1,INDEX(회차설정!$D$13:$D$27,$S$14)-INDEX(회차설정!$C$13:$C$27,$S$14)+1))) | F24: =IF(OR($S$14="",$D24=0,$D24="",$E24=""),"",$E24/$D24*100) | H24: =IF($F24="","",REPT("■",ROUND($F24/5,0)))
A25: =IF($R$3="","","합계") | D25: =IF($R$3="","",SUM(D13:D24)) | E25: =IF($R$3="","",SUM(E13:E24)) | F25: =IF(OR($D25=0,$D25=""),"",$E25/$D25*100) | H25: =IF($F25="","",REPT("■",ROUND($F25/5,0)))
A27: 4. 문항 채점표
A28: 문항 번호 | B28: 1 | C28: 2 | D28: 3 | E28: 4 | F28: 5 | G28: 6 | H28: 7 | I28: 8 | J28: 9 | K28: 10 | L28: 11 | M28: 12 | N28: 13 | O28: 14 | P28: 15
A29: 정답 | B29: =IF($R$4="","",IF($R$4="언어와 매체",자동계산!$D$4,자동계산!$B$4)) | C29: =IF($R$4="","",IF($R$4="언어와 매체",자동계산!$D$5,자동계산!$B$5)) | D29: =IF($R$4="","",IF($R$4="언어와 매체",자동계산!$D$6,자동계산!$B$6)) | E29: =IF($R$4="","",IF($R$4="언어와 매체",자동계산!$D$7,자동계산!$B$7)) | F29: =IF($R$4="","",IF($R$4="언어와 매체",자동계산!$D$8,자동계산!$B$8)) | G29: =IF($R$4="","",IF($R$4="언어와 매체",자동계산!$D$9,자동계산!$B$9)) | H29: =IF($R$4="","",IF($R$4="언어와 매체",자동계산!$D$10,자동계산!$B$10)) | I29: =IF($R$4="","",IF($R$4="언어와 매체",자동계산!$D$11,자동계산!$B$11)) | J29: =IF($R$4="","",IF($R$4="언어와 매체",자동계산!$D$12,자동계산!$B$12)) | K29: =IF($R$4="","",IF($R$4="언어와 매체",자동계산!$D$13,자동계산!$B$13)) | L29: =IF($R$4="","",IF($R$4="언어와 매체",자동계산!$D$14,자동계산!$B$14)) | M29: =IF($R$4="","",IF($R$4="언어와 매체",자동계산!$D$15,자동계산!$B$15)) | N29: =IF($R$4="","",IF($R$4="언어와 매체",자동계산!$D$16,자동계산!$B$16)) | O29: =IF($R$4="","",IF($R$4="언어와 매체",자동계산!$D$17,자동계산!$B$17)) | P29: =IF($R$4="","",IF($R$4="언어와 매체",자동계산!$D$18,자동계산!$B$18))
A30: 학생답안 | B30: =IF($R$3="","",INDEX(전체채점!E$3:E$62,$R$3)) | C30: =IF($R$3="","",INDEX(전체채점!F$3:F$62,$R$3)) | D30: =IF($R$3="","",INDEX(전체채점!G$3:G$62,$R$3)) | E30: =IF($R$3="","",INDEX(전체채점!H$3:H$62,$R$3)) | F30: =IF($R$3="","",INDEX(전체채점!I$3:I$62,$R$3)) | G30: =IF($R$3="","",INDEX(전체채점!J$3:J$62,$R$3)) | H30: =IF($R$3="","",INDEX(전체채점!K$3:K$62,$R$3)) | I30: =IF($R$3="","",INDEX(전체채점!L$3:L$62,$R$3)) | ... P30: =IF($R$3="","",INDEX(전체채점!S$3:S$62,$R$3))
A31: 정오 | B31: =IF($R$3="","",INDEX(전체채점!AX$3:AX$62,$R$3)) | C31: =IF($R$3="","",INDEX(전체채점!AY$3:AY$62,$R$3)) | D31: =IF($R$3="","",INDEX(전체채점!AZ$3:AZ$62,$R$3)) | E31: =IF($R$3="","",INDEX(전체채점!BA$3:BA$62,$R$3)) | F31: =IF($R$3="","",INDEX(전체채점!BB$3:BB$62,$R$3)) | G31: =IF($R$3="","",INDEX(전체채점!BC$3:BC$62,$R$3)) | H31: =IF($R$3="","",INDEX(전체채점!BD$3:BD$62,$R$3)) | I31: =IF($R$3="","",INDEX(전체채점!BE$3:BE$62,$R$3)) | ... P31: =IF($R$3="","",INDEX(전체채점!BL$3:BL$62,$R$3))
A32: 문항 번호 | B32: 16 | C32: 17 | D32: 18 | E32: 19 | F32: 20 | G32: 21 | H32: 22 | I32: 23 | J32: 24 | K32: 25 | L32: 26 | M32: 27 | N32: 28 | O32: 29 | P32: 30
A33: 정답 | B33: =IF($R$4="","",IF($R$4="언어와 매체",자동계산!$D$19,자동계산!$B$19)) | C33: =IF($R$4="","",IF($R$4="언어와 매체",자동계산!$D$20,자동계산!$B$20)) | D33: =IF($R$4="","",IF($R$4="언어와 매체",자동계산!$D$21,자동계산!$B$21)) | E33: =IF($R$4="","",IF($R$4="언어와 매체",자동계산!$D$22,자동계산!$B$22)) | F33: =IF($R$4="","",IF($R$4="언어와 매체",자동계산!$D$23,자동계산!$B$23)) | G33: =IF($R$4="","",IF($R$4="언어와 매체",자동계산!$D$24,자동계산!$B$24)) | H33: =IF($R$4="","",IF($R$4="언어와 매체",자동계산!$D$25,자동계산!$B$25)) | I33: =IF($R$4="","",IF($R$4="언어와 매체",자동계산!$D$26,자동계산!$B$26)) | J33: =IF($R$4="","",IF($R$4="언어와 매체",자동계산!$D$27,자동계산!$B$27)) | K33: =IF($R$4="","",IF($R$4="언어와 매체",자동계산!$D$28,자동계산!$B$28)) | L33: =IF($R$4="","",IF($R$4="언어와 매체",자동계산!$D$29,자동계산!$B$29)) | M33: =IF($R$4="","",IF($R$4="언어와 매체",자동계산!$D$30,자동계산!$B$30)) | N33: =IF($R$4="","",IF($R$4="언어와 매체",자동계산!$D$31,자동계산!$B$31)) | O33: =IF($R$4="","",IF($R$4="언어와 매체",자동계산!$D$32,자동계산!$B$32)) | P33: =IF($R$4="","",IF($R$4="언어와 매체",자동계산!$D$33,자동계산!$B$33))
A34: 학생답안 | B34: =IF($R$3="","",INDEX(전체채점!T$3:T$62,$R$3)) | C34: =IF($R$3="","",INDEX(전체채점!U$3:U$62,$R$3)) | D34: =IF($R$3="","",INDEX(전체채점!V$3:V$62,$R$3)) | E34: =IF($R$3="","",INDEX(전체채점!W$3:W$62,$R$3)) | F34: =IF($R$3="","",INDEX(전체채점!X$3:X$62,$R$3)) | G34: =IF($R$3="","",INDEX(전체채점!Y$3:Y$62,$R$3)) | H34: =IF($R$3="","",INDEX(전체채점!Z$3:Z$62,$R$3)) | I34: =IF($R$3="","",INDEX(전체채점!AA$3:AA$62,$R$3)) | ... P34: =IF($R$3="","",INDEX(전체채점!AH$3:AH$62,$R$3))
A35: 정오 | B35: =IF($R$3="","",INDEX(전체채점!BM$3:BM$62,$R$3)) | C35: =IF($R$3="","",INDEX(전체채점!BN$3:BN$62,$R$3)) | D35: =IF($R$3="","",INDEX(전체채점!BO$3:BO$62,$R$3)) | E35: =IF($R$3="","",INDEX(전체채점!BP$3:BP$62,$R$3)) | F35: =IF($R$3="","",INDEX(전체채점!BQ$3:BQ$62,$R$3)) | G35: =IF($R$3="","",INDEX(전체채점!BR$3:BR$62,$R$3)) | H35: =IF($R$3="","",INDEX(전체채점!BS$3:BS$62,$R$3)) | I35: =IF($R$3="","",INDEX(전체채점!BT$3:BT$62,$R$3)) | ... P35: =IF($R$3="","",INDEX(전체채점!CA$3:CA$62,$R$3))
A36: 문항 번호 | B36: 31 | C36: 32 | D36: 33 | E36: 34 | F36: 35 | G36: 36 | H36: 37 | I36: 38 | J36: 39 | K36: 40 | L36: 41 | M36: 42 | N36: 43 | O36: 44 | P36: 45
A37: 정답 | B37: =IF($R$4="","",IF($R$4="언어와 매체",자동계산!$D$34,자동계산!$B$34)) | C37: =IF($R$4="","",IF($R$4="언어와 매체",자동계산!$D$35,자동계산!$B$35)) | D37: =IF($R$4="","",IF($R$4="언어와 매체",자동계산!$D$36,자동계산!$B$36)) | E37: =IF($R$4="","",IF($R$4="언어와 매체",자동계산!$D$37,자동계산!$B$37)) | F37: =IF($R$4="","",IF($R$4="언어와 매체",자동계산!$D$38,자동계산!$B$38)) | G37: =IF($R$4="","",IF($R$4="언어와 매체",자동계산!$D$39,자동계산!$B$39)) | H37: =IF($R$4="","",IF($R$4="언어와 매체",자동계산!$D$40,자동계산!$B$40)) | I37: =IF($R$4="","",IF($R$4="언어와 매체",자동계산!$D$41,자동계산!$B$41)) | J37: =IF($R$4="","",IF($R$4="언어와 매체",자동계산!$D$42,자동계산!$B$42)) | K37: =IF($R$4="","",IF($R$4="언어와 매체",자동계산!$D$43,자동계산!$B$43)) | L37: =IF($R$4="","",IF($R$4="언어와 매체",자동계산!$D$44,자동계산!$B$44)) | M37: =IF($R$4="","",IF($R$4="언어와 매체",자동계산!$D$45,자동계산!$B$45)) | N37: =IF($R$4="","",IF($R$4="언어와 매체",자동계산!$D$46,자동계산!$B$46)) | O37: =IF($R$4="","",IF($R$4="언어와 매체",자동계산!$D$47,자동계산!$B$47)) | P37: =IF($R$4="","",IF($R$4="언어와 매체",자동계산!$D$48,자동계산!$B$48))
A38: 학생답안 | B38: =IF($R$3="","",INDEX(전체채점!AI$3:AI$62,$R$3)) | C38: =IF($R$3="","",INDEX(전체채점!AJ$3:AJ$62,$R$3)) | D38: =IF($R$3="","",INDEX(전체채점!AK$3:AK$62,$R$3)) | E38: =IF($R$3="","",INDEX(전체채점!AL$3:AL$62,$R$3)) | F38: =IF($R$3="","",INDEX(전체채점!AM$3:AM$62,$R$3)) | G38: =IF($R$3="","",INDEX(전체채점!AN$3:AN$62,$R$3)) | H38: =IF($R$3="","",INDEX(전체채점!AO$3:AO$62,$R$3)) | I38: =IF($R$3="","",INDEX(전체채점!AP$3:AP$62,$R$3)) | ... P38: =IF($R$3="","",INDEX(전체채점!AW$3:AW$62,$R$3))
A39: 정오 | B39: =IF($R$3="","",INDEX(전체채점!CB$3:CB$62,$R$3)) | C39: =IF($R$3="","",INDEX(전체채점!CC$3:CC$62,$R$3)) | D39: =IF($R$3="","",INDEX(전체채점!CD$3:CD$62,$R$3)) | E39: =IF($R$3="","",INDEX(전체채점!CE$3:CE$62,$R$3)) | F39: =IF($R$3="","",INDEX(전체채점!CF$3:CF$62,$R$3)) | G39: =IF($R$3="","",INDEX(전체채점!CG$3:CG$62,$R$3)) | H39: =IF($R$3="","",INDEX(전체채점!CH$3:CH$62,$R$3)) | I39: =IF($R$3="","",INDEX(전체채점!CI$3:CI$62,$R$3)) | ... P39: =IF($R$3="","",INDEX(전체채점!CP$3:CP$62,$R$3))
A42: =IF($R$44="","",회차설정!$B$2&" 성적표")
A44: 1. 학생정보 | R44: =IF(답안입력!$A$4="","",2) | S44: =IF($R$45="","",IFERROR(IF($R$45="언어와 매체",MATCH(1,회차설정!$G$13:$G$27,0),MATCH(1,회차설정!$F$13:$F$27,0)),""))
A45: 성명 | D45: 선택과목 | H45: 학년 | L45: 시행일 | R45: =IF($R$44="","",INDEX(전체채점!$B$3:$B$62,$R$44)) | S45: =IF($R$45="","",IFERROR(IF($R$45="언어와 매체",MATCH(2,회차설정!$G$13:$G$27,0),MATCH(2,회차설정!$F$13:$F$27,0)),""))
...

Sheet 분석
A1: 반 전체 분석
A3: ■ 요약
A4: 응시 인원 | C4: =COUNT(전체채점!$C$3:$C$62)
A5: 평균 점수 | C5: =IFERROR(AVERAGE(전체채점!$C$3:$C$62),"")
A6: 최고 점수 | C6: =IFERROR(MAX(전체채점!$C$3:$C$62),"")
A7: 최저 점수 | C7: =IFERROR(MIN(전체채점!$C$3:$C$62),"")
A8: 화법과 작문 평균 | C8: =IFERROR(AVERAGEIF(전체채점!$B$3:$B$62,"화법과 작문",전체채점!$C$3:$C$62),"")
A9: 언어와 매체 평균 | C9: =IFERROR(AVERAGEIF(전체채점!$B$3:$B$62,"언어와 매체",전체채점!$C$3:$C$62),"")
A10: 성적표(전원) 인쇄 쪽수 | C10: =COUNT(전체채점!$C$3:$C$62)
A12: ■ 등급 분포
A13: 1등급 | B13: 2등급 | C13: 3등급 | D13: 4등급 | E13: 등급 외
A14: =COUNTIF(전체채점!$D$3:$D$62,"1등급") | B14: =COUNTIF(전체채점!$D$3:$D$62,"2등급") | C14: =COUNTIF(전체채점!$D$3:$D$62,"3등급") | D14: =COUNTIF(전체채점!$D$3:$D$62,"4등급") | E14: =COUNTIF(전체채점!$D$3:$D$62,"등급 외")
A15: ■ 공통과목 영역별 반 평균 성취도
A16: 분류 | B16: 영역 | C16: 문항 | D16: 배점 | E16: 반 평균 득점 | F16: 평균 성취도(%) | G16: 막대
A17: =IF($H17="","",IF(INDEX(회차설정!$E$13:$E$27,$H17)<>"공통","",INDEX(회차설정!$A$13:$A$27,$H17))) | B17: =IF($H17="","",IF(INDEX(회차설정!$E$13:$E$27,$H17)<>"공통","",INDEX(회차설정!$B$13:$B$27,$H17))) | C17: =IF($H17="","",IF(INDEX(회차설정!$E$13:$E$27,$H17)<>"공통","",INDEX(회차설정!$C$13:$C$27,$H17)&"~"&INDEX(회차설정!$D$13:$D$27,$H17))) | D17: =IF($A17="","",SUMPRODUCT((자동계산!$A$4:$A$48>=INDEX(회차설정!$C$13:$C$27,$H17))*(자동계산!$A$4:$A$48<=INDEX(회차설정!$D$13:$D$27,$H17))*자동계산!$C$4:$C$48)) | E17: =IF(OR($A17="",$C$4=0),"",SUM(OFFSET(전체채점!$AW$2,1,INDEX(회차설정!$C$13:$C$27,$H17),60,INDEX(회차설정!$D$13:$D$27,$H17)-INDEX(회차설정!$C$13:$C$27,$H17)+1))/$C$4) | F17: =IF(OR($A17="",$D17=0,$D17=""),"",$E17/$D17*100) | G17: =IF($F17="","",REPT("■",ROUND($F17/5,0))) | H17: =IFERROR(MATCH(1,회차설정!$F$13:$F$27,0),"")
A18: =IF($H18="","",IF(INDEX(회차설정!$E$13:$E$27,$H18)<>"공통","",INDEX(회차설정!$A$13:$A$27,$H18))) | B18: =IF($H18="","",IF(INDEX(회차설정!$E$13:$E$27,$H18)<>"공통","",INDEX(회차설정!$B$13:$B$27,$H18))) | C18: =IF($H18="","",IF(INDEX(회차설정!$E$13:$E$27,$H18)<>"공통","",INDEX(회차설정!$C$13:$C$27,$H18)&"~"&INDEX(회차설정!$D$13:$D$27,$H18))) | D18: =IF($A18="","",SUMPRODUCT((자동계산!$A$4:$A$48>=INDEX(회차설정!$C$13:$C$27,$H18))*(자동계산!$A$4:$A$48<=INDEX(회차설정!$D$13:$D$27,$H18))*자동계산!$C$4:$C$48)) | E18: =IF(OR($A18="",$C$4=0),"",SUM(OFFSET(전체채점!$AW$2,1,INDEX(회차설정!$C$13:$C$27,$H18),60,INDEX(회차설정!$D$13:$D$27,$H18)-INDEX(회차설정!$C$13:$C$27,$H18)+1))/$C$4) | F18: =IF(OR($A18="",$D18=0,$D18=""),"",$E18/$D18*100) | G18: =IF($F18="","",REPT("■",ROUND($F18/5,0))) | H18: =IFERROR(MATCH(2,회차설정!$F$13:$F$27,0),"")
A19: =IF($H19="","",IF(INDEX(회차설정!$E$13:$E$27,$H19)<>"공통","",INDEX(회차설정!$A$13:$A$27,$H19))) | B19: =IF($H19="","",IF(INDEX(회차설정!$E$13:$E$27,$H19)<>"공통","",INDEX(회차설정!$B$13:$B$27,$H19))) | C19: =IF($H19="","",IF(INDEX(회차설정!$E$13:$E$27,$H19)<>"공통","",INDEX(회차설정!$C$13:$C$27,$H19)&"~"&INDEX(회차설정!$D$13:$D$27,$H19))) | D19: =IF($A19="","",SUMPRODUCT((자동계산!$A$4:$A$48>=INDEX(회차설정!$C$13:$C$27,$H19))*(자동계산!$A$4:$A$48<=INDEX(회차설정!$D$13:$D$27,$H19))*자동계산!$C$4:$C$48)) | E19: =IF(OR($A19="",$C$4=0),"",SUM(OFFSET(전체채점!$AW$2,1,INDEX(회차설정!$C$13:$C$27,$H19),60,INDEX(회차설정!$D$13:$D$27,$H19)-INDEX(회차설정!$C$13:$C$27,$H19)+1))/$C$4) | F19: =IF(OR($A19="",$D19=0,$D19=""),"",$E19/$D19*100) | G19: =IF($F19="","",REPT("■",ROUND($F19/5,0))) | H19: =IFERROR(MATCH(3,회차설정!$F$13:$F$27,0),"")
A20: =IF($H20="","",IF(INDEX(회차설정!$E$13:$E$27,$H20)<>"공통","",INDEX(회차설정!$A$13:$A$27,$H20))) | B20: =IF($H20="","",IF(INDEX(회차설정!$E$13:$E$27,$H20)<>"공통","",INDEX(회차설정!$B$13:$B$27,$H20))) | C20: =IF($H20="","",IF(INDEX(회차설정!$E$13:$E$27,$H20)<>"공통","",INDEX(회차설정!$C$13:$C$27,$H20)&"~"&INDEX(회차설정!$D$13:$D$27,$H20))) | D20: =IF($A20="","",SUMPRODUCT((자동계산!$A$4:$A$48>=INDEX(회차설정!$C$13:$C$27,$H20))*(자동계산!$A$4:$A$48<=INDEX(회차설정!$D$13:$D$27,$H20))*자동계산!$C$4:$C$48)) | E20: =IF(OR($A20="",$C$4=0),"",SUM(OFFSET(전체채점!$AW$2,1,INDEX(회차설정!$C$13:$C$27,$H20),60,INDEX(회차설정!$D$13:$D$27,$H20)-INDEX(회차설정!$C$13:$C$27,$H20)+1))/$C$4) | F20: =IF(OR($A20="",$D20=0,$D20=""),"",$E20/$D20*100) | G20: =IF($F20="","",REPT("■",ROUND($F20/5,0))) | H20: =IFERROR(MATCH(4,회차설정!$F$13:$F$27,0),"")
A21: =IF($H21="","",IF(INDEX(회차설정!$E$13:$E$27,$H21)<>"공통","",INDEX(회차설정!$A$13:$A$27,$H21))) | B21: =IF($H21="","",IF(INDEX(회차설정!$E$13:$E$27,$H21)<>"공통","",INDEX(회차설정!$B$13:$B$27,$H21))) | C21: =IF($H21="","",IF(INDEX(회차설정!$E$13:$E$27,$H21)<>"공통","",INDEX(회차설정!$C$13:$C$27,$H21)&"~"&INDEX(회차설정!$D$13:$D$27,$H21))) | D21: =IF($A21="","",SUMPRODUCT((자동계산!$A$4:$A$48>=INDEX(회차설정!$C$13:$C$27,$H21))*(자동계산!$A$4:$A$48<=INDEX(회차설정!$D$13:$D$27,$H21))*자동계산!$C$4:$C$48)) | E21: =IF(OR($A21="",$C$4=0),"",SUM(OFFSET(전체채점!$AW$2,1,INDEX(회차설정!$C$13:$C$27,$H21),60,INDEX(회차설정!$D$13:$D$27,$H21)-INDEX(회차설정!$C$13:$C$27,$H21)+1))/$C$4) | F21: =IF(OR($A21="",$D21=0,$D21=""),"",$E21/$D21*100) | G21: =IF($F21="","",REPT("■",ROUND($F21/5,0))) | H21: =IFERROR(MATCH(5,회차설정!$F$13:$F$27,0),"")
A22: =IF($H22="","",IF(INDEX(회차설정!$E$13:$E$27,$H22)<>"공통","",INDEX(회차설정!$A$13:$A$27,$H22))) | B22: =IF($H22="","",IF(INDEX(회차설정!$E$13:$E$27,$H22)<>"공통","",INDEX(회차설정!$B$13:$B$27,$H22))) | C22: =IF($H22="","",IF(INDEX(회차설정!$E$13:$E$27,$H22)<>"공통","",INDEX(회차설정!$C$13:$C$27,$H22)&"~"&INDEX(회차설정!$D$13:$D$27,$H22))) | D22: =IF($A22="","",SUMPRODUCT((자동계산!$A$4:$A$48>=INDEX(회차설정!$C$13:$C$27,$H22))*(자동계산!$A$4:$A$48<=INDEX(회차설정!$D$13:$D$27,$H22))*자동계산!$C$4:$C$48)) | E22: =IF(OR($A22="",$C$4=0),"",SUM(OFFSET(전체채점!$AW$2,1,INDEX(회차설정!$C$13:$C$27,$H22),60,INDEX(회차설정!$D$13:$D$27,$H22)-INDEX(회차설정!$C$13:$C$27,$H22)+1))/$C$4) | F22: =IF(OR($A22="",$D22=0,$D22=""),"",$E22/$D22*100) | G22: =IF($F22="","",REPT("■",ROUND($F22/5,0))) | H22: =IFERROR(MATCH(6,회차설정!$F$13:$F$27,0),"")
A23: =IF($H23="","",IF(INDEX(회차설정!$E$13:$E$27,$H23)<>"공통","",INDEX(회차설정!$A$13:$A$27,$H23))) | B23: =IF($H23="","",IF(INDEX(회차설정!$E$13:$E$27,$H23)<>"공통","",INDEX(회차설정!$B$13:$B$27,$H23))) | C23: =IF($H23="","",IF(INDEX(회차설정!$E$13:$E$27,$H23)<>"공통","",INDEX(회차설정!$C$13:$C$27,$H23)&"~"&INDEX(회차설정!$D$13:$D$27,$H23))) | D23: =IF($A23="","",SUMPRODUCT((자동계산!$A$4:$A$48>=INDEX(회차설정!$C$13:$C$27,$H23))*(자동계산!$A$4:$A$48<=INDEX(회차설정!$D$13:$D$27,$H23))*자동계산!$C$4:$C$48)) | E23: =IF(OR($A23="",$C$4=0),"",SUM(OFFSET(전체채점!$AW$2,1,INDEX(회차설정!$C$13:$C$27,$H23),60,INDEX(회차설정!$D$13:$D$27,$H23)-INDEX(회차설정!$C$13:$C$27,$H23)+1))/$C$4) | F23: =IF(OR($A23="",$D23=0,$D23=""),"",$E23/$D23*100) | G23: =IF($F23="","",REPT("■",ROUND($F23/5,0))) | H23: =IFERROR(MATCH(7,회차설정!$F$13:$F$27,0),"")
A24: =IF($H24="","",IF(INDEX(회차설정!$E$13:$E$27,$H24)<>"공통","",INDEX(회차설정!$A$13:$A$27,$H24))) | B24: =IF($H24="","",IF(INDEX(회차설정!$E$13:$E$27,$H24)<>"공통","",INDEX(회차설정!$B$13:$B$27,$H24))) | C24: =IF($H24="","",IF(INDEX(회차설정!$E$13:$E$27,$H24)<>"공통","",INDEX(회차설정!$C$13:$C$27,$H24)&"~"&INDEX(회차설정!$D$13:$D$27,$H24))) | D24: =IF($A24="","",SUMPRODUCT((자동계산!$A$4:$A$48>=INDEX(회차설정!$C$13:$C$27,$H24))*(자동계산!$A$4:$A$48<=INDEX(회차설정!$D$13:$D$27,$H24))*자동계산!$C$4:$C$48)) | E24: =IF(OR($A24="",$C$4=0),"",SUM(OFFSET(전체채점!$AW$2,1,INDEX(회차설정!$C$13:$C$27,$H24),60,INDEX(회차설정!$D$13:$D$27,$H24)-INDEX(회차설정!$C$13:$C$27,$H24)+1))/$C$4) | F24: =IF(OR($A24="",$D24=0,$D24=""),"",$E24/$D24*100) | G24: =IF($F24="","",REPT("■",ROUND($F24/5,0))) | H24: =IFERROR(MATCH(8,회차설정!$F$13:$F$27,0),"")
A26: ■ 문항별 정답률 (낮은 문항이 많이 틀린 문항입니다)
A27: 번호 | B27: 전체 정답률(%) | C27: 화법과 작문(%) | D27: 언어와 매체(%) | G27: 막대
A28: 1 | B28: =IFERROR(COUNTIF(전체채점!AX$3:AX$62,">0")/$C$4*100,"") | C28: - | D28: - | G28: =IF($B28="","",REPT("■",ROUND($B28/5,0)))
A29: 2 | B29: =IFERROR(COUNTIF(전체채점!AY$3:AY$62,">0")/$C$4*100,"") | C29: - | D29: - | G29: =IF($B29="","",REPT("■",ROUND($B29/5,0)))
A30: 3 | B30: =IFERROR(COUNTIF(전체채점!AZ$3:AZ$62,">0")/$C$4*100,"") | C30: - | D30: - | G30: =IF($B30="","",REPT("■",ROUND($B30/5,0)))
A31: 4 | B31: =IFERROR(COUNTIF(전체채점!BA$3:BA$62,">0")/$C$4*100,"") | C31: - | D31: - | G31: =IF($B31="","",REPT("■",ROUND($B31/5,0)))
A32: 5 | B32: =IFERROR(COUNTIF(전체채점!BB$3:BB$62,">0")/$C$4*100,"") | C32: - | D32: - | G32: =IF($B32="","",REPT("■",ROUND($B32/5,0)))
A33: 6 | B33: =IFERROR(COUNTIF(전체채점!BC$3:BC$62,">0")/$C$4*100,"") | C33: - | D33: - | G33: =IF($B33="","",REPT("■",ROUND($B33/5,0)))
A34: 7 | B34: =IFERROR(COUNTIF(전체채점!BD$3:BD$62,">0")/$C$4*100,"") | C34: - | D34: - | G34: =IF($B34="","",REPT("■",ROUND($B34/5,0)))
A35: 8 | B35: =IFERROR(COUNTIF(전체채점!BE$3:BE$62,">0")/$C$4*100,"") | C35: - | D35: - | G35: =IF($B35="","",REPT("■",ROUND($B35/5,0)))
A36: 9 | B36: =IFERROR(COUNTIF(전체채점!BF$3:BF$62,">0")/$C$4*100,"") | C36: - | D36: - | G36: =IF($B36="","",REPT("■",ROUND($B36/5,0)))
A37: 10 | B37: =IFERROR(COUNTIF(전체채점!BG$3:BG$62,">0")/$C$4*100,"") | C37: - | D37: - | G37: =IF($B37="","",REPT("■",ROUND($B37/5,0)))
A38: 11 | B38: =IFERROR(COUNTIF(전체채점!BH$3:BH$62,">0")/$C$4*100,"") | C38: - | D38: - | G38: =IF($B38="","",REPT("■",ROUND($B38/5,0)))
A39: 12 | B39: =IFERROR(COUNTIF(전체채점!BI$3:BI$62,">0")/$C$4*100,"") | C39: - | D39: - | G39: =IF($B39="","",REPT("■",ROUND($B39/5,0)))
A40: 13 | B40: =IFERROR(COUNTIF(전체채점!BJ$3:BJ$62,">0")/$C$4*100,"") | C40: - | D40: - | G40: =IF($B40="","",REPT("■",ROUND($B40/5,0)))
A41: 14 | B41: =IFERROR(COUNTIF(전체채점!BK$3:BK$62,">0")/$C$4*100,"") | C41: - | D41: - | G41: =IF($B41="","",REPT("■",ROUND($B41/5,0)))
A42: 15 | B42: =IFERROR(COUNTIF(전체채점!BL$3:BL$62,">0")/$C$4*100,"") | C42: - | D42: - | G42: =IF($B42="","",REPT("■",ROUND($B42/5,0)))
A43: 16 | B43: =IFERROR(COUNTIF(전체채점!BM$3:BM$62,">0")/$C$4*100,"") | C43: - | D43: - | G43: =IF($B43="","",REPT("■",ROUND($B43/5,0)))
...

Sheet 자동계산
A1: 자동 계산용 시트입니다. 고치지 마세요.
A2: 회차설정 시트의 값을 문항 순서대로 모아 둔 표입니다.
A3: 번호 | B3: 정답(화작) | C3: 배점(화작) | D3: 정답(언매) | E3: 배점(언매) | F3: 덮음(화작) | G3: 덮음(언매)
A4: 1 | B4: =회차설정!$B$32 | C4: =회차설정!$C$32 | D4: =회차설정!$B$32 | E4: =회차설정!$C$32 | F4: =SUMPRODUCT(((회차설정!$E$13:$E$27="공통")+(회차설정!$E$13:$E$27="화법과 작문"))*(회차설정!$C$13:$C$27<=$A4)*(회차설정!$D$13:$D$27>=$A4)) | G4: =SUMPRODUCT(((회차설정!$E$13:$E$27="공통")+(회차설정!$E$13:$E$27="언어와 매체"))*(회차설정!$C$13:$C$27<=$A4)*(회차설정!$D$13:$D$27>=$A4))
A5: 2 | B5: =회차설정!$B$33 | C5: =회차설정!$C$33 | D5: =회차설정!$B$33 | E5: =회차설정!$C$33 | F5: =SUMPRODUCT(((회차설정!$E$13:$E$27="공통")+(회차설정!$E$13:$E$27="화법과 작문"))*(회차설정!$C$13:$C$27<=$A5)*(회차설정!$D$13:$D$27>=$A5)) | G5: =SUMPRODUCT(((회차설정!$E$13:$E$27="공통")+(회차설정!$E$13:$E$27="언어와 매체"))*(회차설정!$C$13:$C$27<=$A5)*(회차설정!$D$13:$D$27>=$A5))
A6: 3 | B6: =회차설정!$B$34 | C6: =회차설정!$C$34 | D6: =회차설정!$B$34 | E6: =회차설정!$C$34 | F6: =SUMPRODUCT(((회차설정!$E$13:$E$27="공통")+(회차설정!$E$13:$E$27="화법과 작문"))*(회차설정!$C$13:$C$27<=$A6)*(회차설정!$D$13:$D$27>=$A6)) | G6: =SUMPRODUCT(((회차설정!$E$13:$E$27="공통")+(회차설정!$E$13:$E$27="언어와 매체"))*(회차설정!$C$13:$C$27<=$A6)*(회차설정!$D$13:$D$27>=$A6))
A7: 4 | B7: =회차설정!$B$35 | C7: =회차설정!$C$35 | D7: =회차설정!$B$35 | E7: =회차설정!$C$35 | F7: =SUMPRODUCT(((회차설정!$E$13:$E$27="공통")+(회차설정!$E$13:$E$27="화법과 작문"))*(회차설정!$C$13:$C$27<=$A7)*(회차설정!$D$13:$D$27>=$A7)) | G7: =SUMPRODUCT(((회차설정!$E$13:$E$27="공통")+(회차설정!$E$13:$E$27="언어와 매체"))*(회차설정!$C$13:$C$27<=$A7)*(회차설정!$D$13:$D$27>=$A7))
A8: 5 | B8: =회차설정!$B$36 | C8: =회차설정!$C$36 | D8: =회차설정!$B$36 | E8: =회차설정!$C$36 | F8: =SUMPRODUCT(((회차설정!$E$13:$E$27="공통")+(회차설정!$E$13:$E$27="화법과 작문"))*(회차설정!$C$13:$C$27<=$A8)*(회차설정!$D$13:$D$27>=$A8)) | G8: =SUMPRODUCT(((회차설정!$E$13:$E$27="공통")+(회차설정!$E$13:$E$27="언어와 매체"))*(회차설정!$C$13:$C$27<=$A8)*(회차설정!$D$13:$D$27>=$A8))
A9: 6 | B9: =회차설정!$B$37 | C9: =회차설정!$C$37 | D9: =회차설정!$B$37 | E9: =회차설정!$C$37 | F9: =SUMPRODUCT(((회차설정!$E$13:$E$27="공통")+(회차설정!$E$13:$E$27="화법과 작문"))*(회차설정!$C$13:$C$27<=$A9)*(회차설정!$D$13:$D$27>=$A9)) | G9: =SUMPRODUCT(((회차설정!$E$13:$E$27="공통")+(회차설정!$E$13:$E$27="언어와 매체"))*(회차설정!$C$13:$C$27<=$A9)*(회차설정!$D$13:$D$27>=$A9))
A10: 7 | B10: =회차설정!$B$38 | C10: =회차설정!$C$38 | D10: =회차설정!$B$38 | E10: =회차설정!$C$38 | F10: =SUMPRODUCT(((회차설정!$E$13:$E$27="공통")+(회차설정!$E$13:$E$27="화법과 작문"))*(회차설정!$C$13:$C$27<=$A10)*(회차설정!$D$13:$D$27>=$A10)) | G10: =SUMPRODUCT(((회차설정!$E$13:$E$27="공통")+(회차설정!$E$13:$E$27="언어와 매체"))*(회차설정!$C$13:$C$27<=$A10)*(회차설정!$D$13:$D$27>=$A10))
A11: 8 | B11: =회차설정!$B$39 | C11: =회차설정!$C$39 | D11: =회차설정!$B$39 | E11: =회차설정!$C$39 | F11: =SUMPRODUCT(((회차설정!$E$13:$E$27="공통")+(회차설정!$E$13:$E$27="화법과 작문"))*(회차설정!$C$13:$C$27<=$A11)*(회차설정!$D$13:$D$27>=$A11)) | G11: =SUMPRODUCT(((회차설정!$E$13:$E$27="공통")+(회차설정!$E$13:$E$27="언어와 매체"))*(회차설정!$C$13:$C$27<=$A11)*(회차설정!$D$13:$D$27>=$A11))
A12: 9 | B12: =회차설정!$B$40 | C12: =회차설정!$C$40 | D12: =회차설정!$B$40 | E12: =회차설정!$C$40 | F12: =SUMPRODUCT(((회차설정!$E$13:$E$27="공통")+(회차설정!$E$13:$E$27="화법과 작문"))*(회차설정!$C$13:$C$27<=$A12)*(회차설정!$D$13:$D$27>=$A12)) | G12: =SUMPRODUCT(((회차설정!$E$13:$E$27="공통")+(회차설정!$E$13:$E$27="언어와 매체"))*(회차설정!$C$13:$C$27<=$A12)*(회차설정!$D$13:$D$27>=$A12))
A13: 10 | B13: =회차설정!$B$41 | C13: =회차설정!$C$41 | D13: =회차설정!$B$41 | E13: =회차설정!$C$41 | F13: =SUMPRODUCT(((회차설정!$E$13:$E$27="공통")+(회차설정!$E$13:$E$27="화법과 작문"))*(회차설정!$C$13:$C$27<=$A13)*(회차설정!$D$13:$D$27>=$A13)) | G13: =SUMPRODUCT(((회차설정!$E$13:$E$27="공통")+(회차설정!$E$13:$E$27="언어와 매체"))*(회차설정!$C$13:$C$27<=$A13)*(회차설정!$D$13:$D$27>=$A13))
A14: 11 | B14: =회차설정!$B$42 | C14: =회차설정!$C$42 | D14: =회차설정!$B$42 | E14: =회차설정!$C$42 | F14: =SUMPRODUCT(((회차설정!$E$13:$E$27="공통")+(회차설정!$E$13:$E$27="화법과 작문"))*(회차설정!$C$13:$C$27<=$A14)*(회차설정!$D$13:$D$27>=$A14)) | G14: =SUMPRODUCT(((회차설정!$E$13:$E$27="공통")+(회차설정!$E$13:$E$27="언어와 매체"))*(회차설정!$C$13:$C$27<=$A14)*(회차설정!$D$13:$D$27>=$A14))
A15: 12 | B15: =회차설정!$B$43 | C15: =회차설정!$C$43 | D15: =회차설정!$B$43 | E15: =회차설정!$C$43 | F15: =SUMPRODUCT(((회차설정!$E$13:$E$27="공통")+(회차설정!$E$13:$E$27="화법과 작문"))*(회차설정!$C$13:$C$27<=$A15)*(회차설정!$D$13:$D$27>=$A15)) | G15: =SUMPRODUCT(((회차설정!$E$13:$E$27="공통")+(회차설정!$E$13:$E$27="언어와 매체"))*(회차설정!$C$13:$C$27<=$A15)*(회차설정!$D$13:$D$27>=$A15))
A16: 13 | B16: =회차설정!$B$44 | C16: =회차설정!$C$44 | D16: =회차설정!$B$44 | E16: =회차설정!$C$44 | F16: =SUMPRODUCT(((회차설정!$E$13:$E$27="공통")+(회차설정!$E$13:$E$27="화법과 작문"))*(회차설정!$C$13:$C$27<=$A16)*(회차설정!$D$13:$D$27>=$A16)) | G16: =SUMPRODUCT(((회차설정!$E$13:$E$27="공통")+(회차설정!$E$13:$E$27="언어와 매체"))*(회차설정!$C$13:$C$27<=$A16)*(회차설정!$D$13:$D$27>=$A16))
A17: 14 | B17: =회차설정!$B$45 | C17: =회차설정!$C$45 | D17: =회차설정!$B$45 | E17: =회차설정!$C$45 | F17: =SUMPRODUCT(((회차설정!$E$13:$E$27="공통")+(회차설정!$E$13:$E$27="화법과 작문"))*(회차설정!$C$13:$C$27<=$A17)*(회차설정!$D$13:$D$27>=$A17)) | G17: =SUMPRODUCT(((회차설정!$E$13:$E$27="공통")+(회차설정!$E$13:$E$27="언어와 매체"))*(회차설정!$C$13:$C$27<=$A17)*(회차설정!$D$13:$D$27>=$A17))
A18: 15 | B18: =회차설정!$B$46 | C18: =회차설정!$C$46 | D18: =회차설정!$B$46 | E18: =회차설정!$C$46 | F18: =SUMPRODUCT(((회차설정!$E$13:$E$27="공통")+(회차설정!$E$13:$E$27="화법과 작문"))*(회차설정!$C$13:$C$27<=$A18)*(회차설정!$D$13:$D$27>=$A18)) | G18: =SUMPRODUCT(((회차설정!$E$13:$E$27="공통")+(회차설정!$E$13:$E$27="언어와 매체"))*(회차설정!$C$13:$C$27<=$A18)*(회차설정!$D$13:$D$27>=$A18))
A19: 16 | B19: =회차설정!$B$47 | C19: =회차설정!$C$47 | D19: =회차설정!$B$47 | E19: =회차설정!$C$47 | F19: =SUMPRODUCT(((회차설정!$E$13:$E$27="공통")+(회차설정!$E$13:$E$27="화법과 작문"))*(회차설정!$C$13:$C$27<=$A19)*(회차설정!$D$13:$D$27>=$A19)) | G19: =SUMPRODUCT(((회차설정!$E$13:$E$27="공통")+(회차설정!$E$13:$E$27="언어와 매체"))*(회차설정!$C$13:$C$27<=$A19)*(회차설정!$D$13:$D$27>=$A19))
A20: 17 | B20: =회차설정!$B$48 | C20: =회차설정!$C$48 | D20: =회차설정!$B$48 | E20: =회차설정!$C$48 | F20: =SUMPRODUCT(((회차설정!$E$13:$E$27="공통")+(회차설정!$E$13:$E$27="화법과 작문"))*(회차설정!$C$13:$C$27<=$A20)*(회차설정!$D$13:$D$27>=$A20)) | G20: =SUMPRODUCT(((회차설정!$E$13:$E$27="공통")+(회차설정!$E$13:$E$27="언어와 매체"))*(회차설정!$C$13:$C$27<=$A20)*(회차설정!$D$13:$D$27>=$A20))
A21: 18 | B21: =회차설정!$B$49 | C21: =회차설정!$C$49 | D21: =회차설정!$B$49 | E21: =회차설정!$C$49 | F21: =SUMPRODUCT(((회차설정!$E$13:$E$27="공통")+(회차설정!$E$13:$E$27="화법과 작문"))*(회차설정!$C$13:$C$27<=$A21)*(회차설정!$D$13:$D$27>=$A21)) | G21: =SUMPRODUCT(((회차설정!$E$13:$E$27="공통")+(회차설정!$E$13:$E$27="언어와 매체"))*(회차설정!$C$13:$C$27<=$A21)*(회차설정!$D$13:$D$27>=$A21))
A22: 19 | B22: =회차설정!$B$50 | C22: =회차설정!$C$50 | D22: =회차설정!$B$50 | E22: =회차설정!$C$50 | F22: =SUMPRODUCT(((회차설정!$E$13:$E$27="공통")+(회차설정!$E$13:$E$27="화법과 작문"))*(회차설정!$C$13:$C$27<=$A22)*(회차설정!$D$13:$D$27>=$A22)) | G22: =SUMPRODUCT(((회차설정!$E$13:$E$27="공통")+(회차설정!$E$13:$E$27="언어와 매체"))*(회차설정!$C$13:$C$27<=$A22)*(회차설정!$D$13:$D$27>=$A22))
A23: 20 | B23: =회차설정!$B$51 | C23: =회차설정!$C$51 | D23: =회차설정!$B$51 | E23: =회차설정!$C$51 | F23: =SUMPRODUCT(((회차설정!$E$13:$E$27="공통")+(회차설정!$E$13:$E$27="화법과 작문"))*(회차설정!$C$13:$C$27<=$A23)*(회차설정!$D$13:$D$27>=$A23)) | G23: =SUMPRODUCT(((회차설정!$E$13:$E$27="공통")+(회차설정!$E$13:$E$27="언어와 매체"))*(회차설정!$C$13:$C$27<=$A23)*(회차설정!$D$13:$D$27>=$A23))
A24: 21 | B24: =회차설정!$B$52 | C24: =회차설정!$C$52 | D24: =회차설정!$B$52 | E24: =회차설정!$C$52 | F24: =SUMPRODUCT(((회차설정!$E$13:$E$27="공통")+(회차설정!$E$13:$E$27="화법과 작문"))*(회차설정!$C$13:$C$27<=$A24)*(회차설정!$D$13:$D$27>=$A24)) | G24: =SUMPRODUCT(((회차설정!$E$13:$E$27="공통")+(회차설정!$E$13:$E$27="언어와 매체"))*(회차설정!$C$13:$C$27<=$A24)*(회차설정!$D$13:$D$27>=$A24))
A25: 22 | B25: =회차설정!$B$53 | C25: =회차설정!$C$53 | D25: =회차설정!$B$53 | E25: =회차설정!$C$53 | F25: =SUMPRODUCT(((회차설정!$E$13:$E$27="공통")+(회차설정!$E$13:$E$27="화법과 작문"))*(회차설정!$C$13:$C$27<=$A25)*(회차설정!$D$13:$D$27>=$A25)) | G25: =SUMPRODUCT(((회차설정!$E$13:$E$27="공통")+(회차설정!$E$13:$E$27="언어와 매체"))*(회차설정!$C$13:$C$27<=$A25)*(회차설정!$D$13:$D$27>=$A25))
A26: 23 | B26: =회차설정!$B$54 | C26: =회차설정!$C$54 | D26: =회차설정!$B$54 | E26: =회차설정!$C$54 | F26: =SUMPRODUCT(((회차설정!$E$13:$E$27="공통")+(회차설정!$E$13:$E$27="화법과 작문"))*(회차설정!$C$13:$C$27<=$A26)*(회차설정!$D$13:$D$27>=$A26)) | G26: =SUMPRODUCT(((회차설정!$E$13:$E$27="공통")+(회차설정!$E$13:$E$27="언어와 매체"))*(회차설정!$C$13:$C$27<=$A26)*(회차설정!$D$13:$D$27>=$A26))
A27: 24 | B27: =회차설정!$B$55 | C27: =회차설정!$C$55 | D27: =회차설정!$B$55 | E27: =회차설정!$C$55 | F27: =SUMPRODUCT(((회차설정!$E$13:$E$27="공통")+(회차설정!$E$13:$E$27="화법과 작문"))*(회차설정!$C$13:$C$27<=$A27)*(회차설정!$D$13:$D$27>=$A27)) | G27: =SUMPRODUCT(((회차설정!$E$13:$E$27="공통")+(회차설정!$E$13:$E$27="언어와 매체"))*(회차설정!$C$13:$C$27<=$A27)*(회차설정!$D$13:$D$27>=$A27))
A28: 25 | B28: =회차설정!$B$56 | C28: =회차설정!$C$56 | D28: =회차설정!$B$56 | E28: =회차설정!$C$56 | F28: =SUMPRODUCT(((회차설정!$E$13:$E$27="공통")+(회차설정!$E$13:$E$27="화법과 작문"))*(회차설정!$C$13:$C$27<=$A28)*(회차설정!$D$13:$D$27>=$A28)) | G28: =SUMPRODUCT(((회차설정!$E$13:$E$27="공통")+(회차설정!$E$13:$E$27="언어와 매체"))*(회차설정!$C$13:$C$27<=$A28)*(회차설정!$D$13:$D$27>=$A28))
A29: 26 | B29: =회차설정!$B$57 | C29: =회차설정!$C$57 | D29: =회차설정!$B$57 | E29: =회차설정!$C$57 | F29: =SUMPRODUCT(((회차설정!$E$13:$E$27="공통")+(회차설정!$E$13:$E$27="화법과 작문"))*(회차설정!$C$13:$C$27<=$A29)*(회차설정!$D$13:$D$27>=$A29)) | G29: =SUMPRODUCT(((회차설정!$E$13:$E$27="공통")+(회차설정!$E$13:$E$27="언어와 매체"))*(회차설정!$C$13:$C$27<=$A29)*(회차설정!$D$13:$D$27>=$A29))
